Workbook

Sheet Input Data
B2: CASING RUNNING CALCULATOR — INPUT DATA
B3: Yellow cells are for data input. Others are calculated automatically.
B4: Parameter | C4: Value | D4: Unit | E4: Note | G4: Section No. | H4: Top MD, m | I4: Bottom MD, m | J4: OD, mm | K4: ID, mm | L4: Steel | M4: Yp, MPa | N4: Weight, kg/m
B5: 1. Well and Casing String | G5: 1 | H5: 0 | I5: ='Input Data'!$C$11 | J5: ='Input Data'!$C$7 | K5: ='Input Data'!$C$8 | L5: ='Input Data'!$C$12 | M5: ='Input Data'!$C$13 | N5: ='Input Data'!$C$10
B6: Well Depth (TD) | C6: 3800 | D6: m | E6: Planned Total Depth | G6: 2 | H6: 99999 | I6: 99999
B7: Casing Outer Diameter (OD) | C7: 244.5 | D7: mm | E7: e.g. 9-5/8" = 244.5 mm | G7: 3 | H7: 99999 | I7: 99999
B8: Casing Inner Diameter (ID) | C8: 220.5 | D8: mm | E8: Based on wall thickness
B9: Wall thickness | C9: =($C$7-$C$8)/2 | D9: mm | E9: Calculated
B10: Weight per meter | C10: 69.94 | D10: kg/m | E10: Reference value
B11: Casing shoe depth | C11: 3450 | D11: m | E11: Usually ≤ TD
B12: Steel Grade | C12: P110 | D12: — | E12: J55/K55/N80/L80/P110 и т.д.
B13: Steel Yield Strength | C13: 758 | D13: MPa | E13: For P110 ≈ 758 MPa
B14: Steel Young's Modulus (E) | C14: 210 | D14: ГПа | E14: Steel ≈ 210 GPa
B15: Steel density | C15: 7850 | D15: kg/m³ | E15: Reference
B16: Pipe cross-sectional area | C16: =PI()*($C$7^2-$C$8^2)/4 | D16: мм² | E16: Calculated
B18: 2. Wellbore
B19: Open hole diameter | C19: 311.2 | D19: mm | E19: e.g. 12-1/4" = 311.2 mm
B20: Previous casing ID | C20: 317.9 | D20: mm | E20: e.g. 13-3/8" = 339.7 mm OD, ID ≈ 317.9
B21: Previous casing shoe depth | C21: 1800 | D21: m | E21: Cased/open hole boundary
B23: 3. Well Profile (Survey)
B24: Kick-off Point (KOP) | C24: 600 | D24: m | E24: Inclination build start depth
B25: Dogleg Severity (DLS) | C25: 3 | D25: deg/30m | E25: Typical 2-4 deg/30m
B26: Max inclination angle at TD | C26: 45 | D26: deg | E26: Max deviation from vertical
B27: Azimuth | C27: 90 | D27: deg | E27: See "Well Profile" sheet
B29: 4. Drilling Fluid
B30: Drilling fluid density | C30: 1350 | D30: kg/m³ | E30: 1.35 г/см³
B31: Plastic Viscosity (PV) | C31: 25 | D31: cP | E31: Plastic viscosity
B32: Yield Point (YP) | C32: 15 | D32: Pa | E32: Yield Point
B33: Mud surface temperature | C33: 20 | D33: °C | E33: Initial temperature
B34: Geothermal gradient | C34: 3 | D34: °C/100m | E34: Typical 2.5-3.5
B35: Bottomhole mud temperature | C35: =$C$33+$C$34*'Well Profile'!$D$15/100 | D35: °C | E35: Расчёт
B37: 5. Friction Coefficients (CoF)
B38: Cased hole friction coefficient (μ_c) | C38: 0.25 | D38: — | E38: Typical 0.20-0.30
B39: Open hole friction coefficient (μ_o) | C39: 0.35 | D39: — | E39: Typical 0.30-0.45
B41: 6. Equipment and Limits
B42: Rig capacity | C42: 250 | D42: t | E42: Max hook load
B43: Block and tackle weight | C43: 15 | D43: t | E43: Hook block + lines weight
B44: Maximum allowed overpull | C44: 200 | D44: t | E44: Tension limit
B45: Maximum allowed slack-off | C45: 180 | D45: t | E45: Compression limit (slack-off)
B46: Safety factor | C46: 1.3 | D46: — | E46: For load
...

Sheet Well Profile
B2: WELLBORE PROFILE — DIRECTIONAL SURVEY
B4: No. | C4: MD, m | D4: TVD, m | E4: Inclination, ° | F4: Azimuth, ° | G4: Section Type | H4: DLS, °/30m
B5: 1 | C5: 0 | D5: 0 | E5: 0 | F5: 90 | G5: Vertical | H5: 0
B6: 2 | C6: 300 | D6: 300 | E6: 0 | F6: 90 | G6: Vertical | H6: =ABS(E6-E5)/(C6-C5)*30
B7: 3 | C7: 600 | D7: 600 | E7: 0 | F7: 90 | G7: Vertical (KOP) | H7: =ABS(E7-E6)/(C7-C6)*30
B8: 4 | C8: 750 | D8: 748 | E8: 15 | F8: 90 | G8: Build | H8: =ABS(E8-E7)/(C8-C7)*30
B9: 5 | C9: 900 | D9: 891 | E9: 30 | F9: 90 | G9: Build | H9: =ABS(E9-E8)/(C9-C8)*30
B10: 6 | C10: 1050 | D10: 1024 | E10: 45 | F10: 90 | G10: Build (EOC) | H10: =ABS(E10-E9)/(C10-C9)*30
B11: 7 | C11: 1500 | D11: 1341 | E11: 45 | F11: 90 | G11: Tangent | H11: =ABS(E11-E10)/(C11-C10)*30
B12: 8 | C12: 2000 | D12: 1694 | E12: 45 | F12: 90 | G12: Tangent | H12: =ABS(E12-E11)/(C12-C11)*30
B13: 9 | C13: 2500 | D13: 2048 | E13: 45 | F13: 90 | G13: Tangent | H13: =ABS(E13-E12)/(C13-C12)*30
B14: 10 | C14: 3000 | D14: 2401 | E14: 45 | F14: 90 | G14: Tangent | H14: =ABS(E14-E13)/(C14-C13)*30
B15: 11 | C15: 3450 | D15: 2695 | E15: 45 | F15: 90 | G15: Tangent (TD) | H15: =ABS(E15-E14)/(C15-C14)*30

Sheet Calculations
B2: CASING RUNNING EVALUATION — INTERVAL ANALYSIS
B3: Total intervals: 10. Highlighted rows represent hazardous intervals (buckling/slack-off/overpull/pressures). Hook loads are integrated from bottom to top; compression is integrated from top to bottom.
B4: No. | C4: Top MD, m | D4: Bottom MD, m | E4: ΔL, m | F4: Top Inc, ° | G4: Bottom Inc, ° | H4: Avg Inc, ° | I4: Hole Type | J4: μ | K4: Air Weight, t | L4: Buoyant Weight, t | M4: Axial Weight, t | N4: Normal Force, t | O4: Friction Force, t | P4: Acc. Friction, t | Q4: Acc. Axial Weight, t | R4: Hook Load (RIH), t | S4: Hook Load (POOH), t | T4: Compressive Force, t | U4: Crit. Sinusoidal, t | V4: Crit. Helical, t | W4: Buckling Factor | X4: Temp., °C | Y4: Status | Z4: OD, mm | AA4: ID, mm | AB4: Yp, MPa | AC4: Weight, kg/m | AD4: t, mm | AE4: I, m⁴ | AF4: r, m | AG4: P_coll_res, MPa | AH4: P_burst_res, MPa | AI4: P_hydro, MPa | AJ4: v_ann, m/s | AK4: dP/dz, Pa/m | AL4: P_surge, MPa | AM4: P_total, MPa | AN4: ECD, kg/m³ | AO4: SF_ECD | AP4: VM Stress, MPa | AQ4: SF_Strength | AR4: SF_Collapse | AS4: SF_Burst
B5: 1 | C5: ='Well Profile'!C5 | D5: ='Well Profile'!C6 | E5: =D5-C5 | F5: ='Well Profile'!E5 | G5: ='Well Profile'!E6 | H5: =(F5+G5)/2 | I5: =IF(C5<'Input Data'!$C$21,"cased","open") | J5: =IF(I5="cased",'Input Data'!$C$38,'Input Data'!$C$39) | K5: =AC5*E5/1000 | L5: =K5*'Input Data'!$C$50 | M5: =L5*COS(RADIANS(H5)) | N5: =SQRT((L5*SIN(RADIANS(H5)))^2 + (Q5*ABS(G5-F5)*PI()/180)^2) | O5: =N5*J5 | P5: =O5+P6 | Q5: =M5+Q6 | R5: =Q5-P5+'Input Data'!$C$43 | S5: =Q5+P5+'Input Data'!$C$43 | T5: ='Input Data'!$C$45 - Q6 + P6 | U5: =IF(H5<1, 1.94*(('Input Data'!$C$52*AE5*('Input Data'!$C$54^2))^(1/3))/('Input Data'!$C$57*1000), 2*SQRT('Input Data'!$C$52*AE5*'Input Data'!$C$54*SIN(RADIANS(H5))/AF5)/('Input Data'!$C$57*1000)) | V5: =2*U5 | W5: =IFERROR(IF(T5>0,T5/V5,0),0) | X5: ='Input Data'!$C$33+'Input Data'!$C$34*((C5+D5)/2)/100 | Y5: =IF(W5>1,"DANGER: Helical Buckling",IF(W5>0.5,"Warning: Sinusoidal Buckling",IF(AO5<1,"DANGER: Fracture (ECD Limit)",IF(AR5<1.15,"DANGER: Casing Collapse",IF(AS5<1.1,"DANGER: Casing Burst",IF(AQ5<1.25,"DANGER: Yield Stress",IF(ROW()=5,IF(S5>'Input Data'!$C$44,"Overpull Limit Exceeded",IF(R5<'Input Data'!$C$43,"Slack-off Required",IF(R5>'Input Data'!$C$42,"Rig Capacity Exceeded","Normal"))),"Normal"))))))) | Z5: =LOOKUP((C5+D5)/2, 'Input Data'!$H$5:$H$7, 'Input Data'!$J$5:$J$7) | AA5: =LOOKUP((C5+D5)/2, 'Input Data'!$H$5:$H$7, 'Input Data'!$K$5:$K$7) | AB5: =LOOKUP((C5+D5)/2, 'Input Data'!$H$5:$H$7, 'Input Data'!$M$5:$M$7) | AC5: =LOOKUP((C5+D5)/2, 'Input Data'!$H$5:$H$7, 'Input Data'!$N$5:$N$7) | AD5: =(Z5-AA5)/2 | AE5: =PI()/64*((Z5/1000)^4-(AA5/1000)^4) | AF5: =(IF(I5="cased", 'Input Data'!$C$20, 'Input Data'!$C$19)-Z5)/2000 | AG5: =1 / ( 1 / (2 * ('Input Data'!$C$14 * 1000) / 0.91 / ((Z5/AD5) * (Z5/AD5 - 1)^2)) + 1 / (2 * AB5 * ((Z5/AD5) - 1) / (Z5/AD5)^2) ) | AH5: =0.875 * 2 * AB5 * AD5 / Z5 | AI5: ='Input Data'!$C$30 * 'Input Data'!$C$57 * 'Well Profile'!D6 / 1000000 | AJ5: ='Input Data'!$C$47 * ( (Z5/1000)^2 / ( (IF(I5="cased",'Input Data'!$C$20,'Input Data'!$C$19)/1000)^2 - (Z5/1000)^2 ) + 0.4 ) | AK5: =12 * ('Input Data'!$C$31/1000) * AJ5 / (AF5*2)^2 + 6 * 'Input Data'!$C$32 / (AF5*2) | AL5: =AK5*E5/1000000 | AM5: =AI5+AL5 | AN5: =AM5*1000000/('Input Data'!$C$57*'Well Profile'!D6) | AO5: ='Input Data'!$C$58/AN5 | AP5: =SQRT(((Q5+P5)*9810/(PI()*(Z5^2-AA5^2)/4))^2 + ('Input Data'!$C$59*Z5/(2*AD5))^2 + (-( 'Input Data'!$C$59 + 2*AI5 ) / 2)^2 - ((Q5+P5)*9810/(PI()*(Z5^2-AA5^2)/4))*('Input Data'!$C$59*Z5/(2*AD5)) - ('Input Data'!$C$59*Z5/(2*AD5))*(-( 'Input Data'!$C$59 + 2*AI5 ) / 2) - (-( 'Input Data'!$C$59 + 2*AI5 ) / 2)*((Q5+P5)*9810/(PI()*(Z5^2-AA5^2)/4))) | AQ5: =AB5/AP5 | AR5: =AG5/AI5 | AS5: =AH5/30
B6: 2 | C6: ='Well Profile'!C6 | D6: ='Well Profile'!C7 | E6: =D6-C6 | F6: ='Well Profile'!E6 | G6: ='Well Profile'!E7 | H6: =(F6+G6)/2 | I6: =IF(C6<'Input Data'!$C$21,"cased","open") | J6: =IF(I6="cased",'Input Data'!$C$38,'Input Data'!$C$39) | K6: =AC6*E6/1000 | L6: =K6*'Input Data'!$C$50 | M6: =L6*COS(RADIANS(H6)) | N6: =SQRT((L6*SIN(RADIANS(H6)))^2 + (Q6*ABS(G6-F6)*PI()/180)^2) | O6: =N6*J6 | P6: =O6+P7 | Q6: =M6+Q7 | R6: =Q6-P6+'Input Data'!$C$43 | S6: =Q6+P6+'Input Data'!$C$43 | T6: ='Input Data'!$C$45 - Q7 + P7 | U6: =IF(H6<1, 1.94*(('Input Data'!$C$52*AE6*('Input Data'!$C$54^2))^(1/3))/('Input Data'!$C$57*1000), 2*SQRT('Input Data'!$C$52*AE6*'Input Data'!$C$54*SIN(RADIANS(H6))/AF6)/('Input Data'!$C$57*1000)) | V6: =2*U6 | W6: =IFERROR(IF(T6>0,T6/V6,0),0) | X6: ='Input Data'!$C$33+'Input Data'!$C$34*((C6+D6)/2)/100 | Y6: =IF(W6>1,"DANGER: Helical Buckling",IF(W6>0.5,"Warning: Sinusoidal Buckling",IF(AO6<1,"DANGER: Fracture (ECD Limit)",IF(AR6<1.15,"DANGER: Casing Collapse",IF(AS6<1.1,"DANGER: Casing Burst",IF(AQ6<1.25,"DANGER: Yield Stress",IF(ROW()=5,IF(S6>'Input Data'!$C$44,"Overpull Limit Exceeded",IF(R6<'Input Data'!$C$43,"Slack-off Required",IF(R6>'Input Data'!$C$42,"Rig Capacity Exceeded","Normal"))),"Normal"))))))) | Z6: =LOOKUP((C6+D6)/2, 'Input Data'!$H$5:$H$7, 'Input Data'!$J$5:$J$7) | AA6: =LOOKUP((C6+D6)/2, 'Input Data'!$H$5:$H$7, 'Input Data'!$K$5:$K$7) | AB6: =LOOKUP((C6+D6)/2, 'Input Data'!$H$5:$H$7, 'Input Data'!$M$5:$M$7) | AC6: =LOOKUP((C6+D6)/2, 'Input Data'!$H$5:$H$7, 'Input Data'!$N$5:$N$7) | AD6: =(Z6-AA6)/2 | AE6: =PI()/64*((Z6/1000)^4-(AA6/1000)^4) | AF6: =(IF(I6="cased", 'Input Data'!$C$20, 'Input Data'!$C$19)-Z6)/2000 | AG6: =1 / ( 1 / (2 * ('Input Data'!$C$14 * 1000) / 0.91 / ((Z6/AD6) * (Z6/AD6 - 1)^2)) + 1 / (2 * AB6 * ((Z6/AD6) - 1) / (Z6/AD6)^2) ) | AH6: =0.875 * 2 * AB6 * AD6 / Z6 | AI6: ='Input Data'!$C$30 * 'Input Data'!$C$57 * 'Well Profile'!D7 / 1000000 | AJ6: ='Input Data'!$C$47 * ( (Z6/1000)^2 / ( (IF(I6="cased",'Input Data'!$C$20,'Input Data'!$C$19)/1000)^2 - (Z6/1000)^2 ) + 0.4 ) | AK6: =12 * ('Input Data'!$C$31/1000) * AJ6 / (AF6*2)^2 + 6 * 'Input Data'!$C$32 / (AF6*2) | AL6: =AL5+AK6*E6/1000000 | AM6: =AI6+AL6 | AN6: =AM6*1000000/('Input Data'!$C$57*'Well Profile'!D7) | AO6: ='Input Data'!$C$58/AN6 | AP6: =SQRT(((Q6+P6)*9810/(PI()*(Z6^2-AA6^2)/4))^2 + ('Input Data'!$C$59*Z6/(2*AD6))^2 + (-( 'Input Data'!$C$59 + 2*AI6 ) / 2)^2 - ((Q6+P6)*9810/(PI()*(Z6^2-AA6^2)/4))*('Input Data'!$C$59*Z6/(2*AD6)) - ('Input Data'!$C$59*Z6/(2*AD6))*(-( 'Input Data'!$C$59 + 2*AI6 ) / 2) - (-( 'Input Data'!$C$59 + 2*AI6 ) / 2)*((Q6+P6)*9810/(PI()*(Z6^2-AA6^2)/4))) | AQ6: =AB6/AP6 | AR6: =AG6/AI6 | AS6: =AH6/30
B7: 3 | C7: ='Well Profile'!C7 | D7: ='Well Profile'!C8 | E7: =D7-C7 | F7: ='Well Profile'!E7 | G7: ='Well Profile'!E8 | H7: =(F7+G7)/2 | I7: =IF(C7<'Input Data'!$C$21,"cased","open") | J7: =IF(I7="cased",'Input Data'!$C$38,'Input Data'!$C$39) | K7: =AC7*E7/1000 | L7: =K7*'Input Data'!$C$50 | M7: =L7*COS(RADIANS(H7)) | N7: =SQRT((L7*SIN(RADIANS(H7)))^2 + (Q7*ABS(G7-F7)*PI()/180)^2) | O7: =N7*J7 | P7: =O7+P8 | Q7: =M7+Q8 | R7: =Q7-P7+'Input Data'!$C$43 | S7: =Q7+P7+'Input Data'!$C$43 | T7: ='Input Data'!$C$45 - Q8 + P8 | U7: =IF(H7<1, 1.94*(('Input Data'!$C$52*AE7*('Input Data'!$C$54^2))^(1/3))/('Input Data'!$C$57*1000), 2*SQRT('Input Data'!$C$52*AE7*'Input Data'!$C$54*SIN(RADIANS(H7))/AF7)/('Input Data'!$C$57*1000)) | V7: =2*U7 | W7: =IFERROR(IF(T7>0,T7/V7,0),0) | X7: ='Input Data'!$C$33+'Input Data'!$C$34*((C7+D7)/2)/100 | Y7: =IF(W7>1,"DANGER: Helical Buckling",IF(W7>0.5,"Warning: Sinusoidal Buckling",IF(AO7<1,"DANGER: Fracture (ECD Limit)",IF(AR7<1.15,"DANGER: Casing Collapse",IF(AS7<1.1,"DANGER: Casing Burst",IF(AQ7<1.25,"DANGER: Yield Stress",IF(ROW()=5,IF(S7>'Input Data'!$C$44,"Overpull Limit Exceeded",IF(R7<'Input Data'!$C$43,"Slack-off Required",IF(R7>'Input Data'!$C$42,"Rig Capacity Exceeded","Normal"))),"Normal"))))))) | Z7: =LOOKUP((C7+D7)/2, 'Input Data'!$H$5:$H$7, 'Input Data'!$J$5:$J$7) | AA7: =LOOKUP((C7+D7)/2, 'Input Data'!$H$5:$H$7, 'Input Data'!$K$5:$K$7) | AB7: =LOOKUP((C7+D7)/2, 'Input Data'!$H$5:$H$7, 'Input Data'!$M$5:$M$7) | AC7: =LOOKUP((C7+D7)/2, 'Input Data'!$H$5:$H$7, 'Input Data'!$N$5:$N$7) | AD7: =(Z7-AA7)/2 | AE7: =PI()/64*((Z7/1000)^4-(AA7/1000)^4) | AF7: =(IF(I7="cased", 'Input Data'!$C$20, 'Input Data'!$C$19)-Z7)/2000 | AG7: =1 / ( 1 / (2 * ('Input Data'!$C$14 * 1000) / 0.91 / ((Z7/AD7) * (Z7/AD7 - 1)^2)) + 1 / (2 * AB7 * ((Z7/AD7) - 1) / (Z7/AD7)^2) ) | AH7: =0.875 * 2 * AB7 * AD7 / Z7 | AI7: ='Input Data'!$C$30 * 'Input Data'!$C$57 * 'Well Profile'!D8 / 1000000 | AJ7: ='Input Data'!$C$47 * ( (Z7/1000)^2 / ( (IF(I7="cased",'Input Data'!$C$20,'Input Data'!$C$19)/1000)^2 - (Z7/1000)^2 ) + 0.4 ) | AK7: =12 * ('Input Data'!$C$31/1000) * AJ7 / (AF7*2)^2 + 6 * 'Input Data'!$C$32 / (AF7*2) | AL7: =AL6+AK7*E7/1000000 | AM7: =AI7+AL7 | AN7: =AM7*1000000/('Input Data'!$C$57*'Well Profile'!D8) | AO7: ='Input Data'!$C$58/AN7 | AP7: =SQRT(((Q7+P7)*9810/(PI()*(Z7^2-AA7^2)/4))^2 + ('Input Data'!$C$59*Z7/(2*AD7))^2 + (-( 'Input Data'!$C$59 + 2*AI7 ) / 2)^2 - ((Q7+P7)*9810/(PI()*(Z7^2-AA7^2)/4))*('Input Data'!$C$59*Z7/(2*AD7)) - ('Input Data'!$C$59*Z7/(2*AD7))*(-( 'Input Data'!$C$59 + 2*AI7 ) / 2) - (-( 'Input Data'!$C$59 + 2*AI7 ) / 2)*((Q7+P7)*9810/(PI()*(Z7^2-AA7^2)/4))) | AQ7: =AB7/AP7 | AR7: =AG7/AI7 | AS7: =AH7/30
B8: 4 | C8: ='Well Profile'!C8 | D8: ='Well Profile'!C9 | E8: =D8-C8 | F8: ='Well Profile'!E8 | G8: ='Well Profile'!E9 | H8: =(F8+G8)/2 | I8: =IF(C8<'Input Data'!$C$21,"cased","open") | J8: =IF(I8="cased",'Input Data'!$C$38,'Input Data'!$C$39) | K8: =AC8*E8/1000 | L8: =K8*'Input Data'!$C$50 | M8: =L8*COS(RADIANS(H8)) | N8: =SQRT((L8*SIN(RADIANS(H8)))^2 + (Q8*ABS(G8-F8)*PI()/180)^2) | O8: =N8*J8 | P8: =O8+P9 | Q8: =M8+Q9 | R8: =Q8-P8+'Input Data'!$C$43 | S8: =Q8+P8+'Input Data'!$C$43 | T8: ='Input Data'!$C$45 - Q9 + P9 | U8: =IF(H8<1, 1.94*(('Input Data'!$C$52*AE8*('Input Data'!$C$54^2))^(1/3))/('Input Data'!$C$57*1000), 2*SQRT('Input Data'!$C$52*AE8*'Input Data'!$C$54*SIN(RADIANS(H8))/AF8)/('Input Data'!$C$57*1000)) | V8: =2*U8 | W8: =IFERROR(IF(T8>0,T8/V8,0),0) | X8: ='Input Data'!$C$33+'Input Data'!$C$34*((C8+D8)/2)/100 | Y8: =IF(W8>1,"DANGER: Helical Buckling",IF(W8>0.5,"Warning: Sinusoidal Buckling",IF(AO8<1,"DANGER: Fracture (ECD Limit)",IF(AR8<1.15,"DANGER: Casing Collapse",IF(AS8<1.1,"DANGER: Casing Burst",IF(AQ8<1.25,"DANGER: Yield Stress",IF(ROW()=5,IF(S8>'Input Data'!$C$44,"Overpull Limit Exceeded",IF(R8<'Input Data'!$C$43,"Slack-off Required",IF(R8>'Input Data'!$C$42,"Rig Capacity Exceeded","Normal"))),"Normal"))))))) | Z8: =LOOKUP((C8+D8)/2, 'Input Data'!$H$5:$H$7, 'Input Data'!$J$5:$J$7) | AA8: =LOOKUP((C8+D8)/2, 'Input Data'!$H$5:$H$7, 'Input Data'!$K$5:$K$7) | AB8: =LOOKUP((C8+D8)/2, 'Input Data'!$H$5:$H$7, 'Input Data'!$M$5:$M$7) | AC8: =LOOKUP((C8+D8)/2, 'Input Data'!$H$5:$H$7, 'Input Data'!$N$5:$N$7) | AD8: =(Z8-AA8)/2 | AE8: =PI()/64*((Z8/1000)^4-(AA8/1000)^4) | AF8: =(IF(I8="cased", 'Input Data'!$C$20, 'Input Data'!$C$19)-Z8)/2000 | AG8: =1 / ( 1 / (2 * ('Input Data'!$C$14 * 1000) / 0.91 / ((Z8/AD8) * (Z8/AD8 - 1)^2)) + 1 / (2 * AB8 * ((Z8/AD8) - 1) / (Z8/AD8)^2) ) | AH8: =0.875 * 2 * AB8 * AD8 / Z8 | AI8: ='Input Data'!$C$30 * 'Input Data'!$C$57 * 'Well Profile'!D9 / 1000000 | AJ8: ='Input Data'!$C$47 * ( (Z8/1000)^2 / ( (IF(I8="cased",'Input Data'!$C$20,'Input Data'!$C$19)/1000)^2 - (Z8/1000)^2 ) + 0.4 ) | AK8: =12 * ('Input Data'!$C$31/1000) * AJ8 / (AF8*2)^2 + 6 * 'Input Data'!$C$32 / (AF8*2) | AL8: =AL7+AK8*E8/1000000 | AM8: =AI8+AL8 | AN8: =AM8*1000000/('Input Data'!$C$57*'Well Profile'!D9) | AO8: ='Input Data'!$C$58/AN8 | AP8: =SQRT(((Q8+P8)*9810/(PI()*(Z8^2-AA8^2)/4))^2 + ('Input Data'!$C$59*Z8/(2*AD8))^2 + (-( 'Input Data'!$C$59 + 2*AI8 ) / 2)^2 - ((Q8+P8)*9810/(PI()*(Z8^2-AA8^2)/4))*('Input Data'!$C$59*Z8/(2*AD8)) - ('Input Data'!$C$59*Z8/(2*AD8))*(-( 'Input Data'!$C$59 + 2*AI8 ) / 2) - (-( 'Input Data'!$C$59 + 2*AI8 ) / 2)*((Q8+P8)*9810/(PI()*(Z8^2-AA8^2)/4))) | AQ8: =AB8/AP8 | AR8: =AG8/AI8 | AS8: =AH8/30
B9: 5 | C9: ='Well Profile'!C9 | D9: ='Well Profile'!C10 | E9: =D9-C9 | F9: ='Well Profile'!E9 | G9: ='Well Profile'!E10 | H9: =(F9+G9)/2 | I9: =IF(C9<'Input Data'!$C$21,"cased","open") | J9: =IF(I9="cased",'Input Data'!$C$38,'Input Data'!$C$39) | K9: =AC9*E9/1000 | L9: =K9*'Input Data'!$C$50 | M9: =L9*COS(RADIANS(H9)) | N9: =SQRT((L9*SIN(RADIANS(H9)))^2 + (Q9*ABS(G9-F9)*PI()/180)^2) | O9: =N9*J9 | P9: =O9+P10 | Q9: =M9+Q10 | R9: =Q9-P9+'Input Data'!$C$43 | S9: =Q9+P9+'Input Data'!$C$43 | T9: ='Input Data'!$C$45 - Q10 + P10 | U9: =IF(H9<1, 1.94*(('Input Data'!$C$52*AE9*('Input Data'!$C$54^2))^(1/3))/('Input Data'!$C$57*1000), 2*SQRT('Input Data'!$C$52*AE9*'Input Data'!$C$54*SIN(RADIANS(H9))/AF9)/('Input Data'!$C$57*1000)) | V9: =2*U9 | W9: =IFERROR(IF(T9>0,T9/V9,0),0) | X9: ='Input Data'!$C$33+'Input Data'!$C$34*((C9+D9)/2)/100 | Y9: =IF(W9>1,"DANGER: Helical Buckling",IF(W9>0.5,"Warning: Sinusoidal Buckling",IF(AO9<1,"DANGER: Fracture (ECD Limit)",IF(AR9<1.15,"DANGER: Casing Collapse",IF(AS9<1.1,"DANGER: Casing Burst",IF(AQ9<1.25,"DANGER: Yield Stress",IF(ROW()=5,IF(S9>'Input Data'!$C$44,"Overpull Limit Exceeded",IF(R9<'Input Data'!$C$43,"Slack-off Required",IF(R9>'Input Data'!$C$42,"Rig Capacity Exceeded","Normal"))),"Normal"))))))) | Z9: =LOOKUP((C9+D9)/2, 'Input Data'!$H$5:$H$7, 'Input Data'!$J$5:$J$7) | AA9: =LOOKUP((C9+D9)/2, 'Input Data'!$H$5:$H$7, 'Input Data'!$K$5:$K$7) | AB9: =LOOKUP((C9+D9)/2, 'Input Data'!$H$5:$H$7, 'Input Data'!$M$5:$M$7) | AC9: =LOOKUP((C9+D9)/2, 'Input Data'!$H$5:$H$7, 'Input Data'!$N$5:$N$7) | AD9: =(Z9-AA9)/2 | AE9: =PI()/64*((Z9/1000)^4-(AA9/1000)^4) | AF9: =(IF(I9="cased", 'Input Data'!$C$20, 'Input Data'!$C$19)-Z9)/2000 | AG9: =1 / ( 1 / (2 * ('Input Data'!$C$14 * 1000) / 0.91 / ((Z9/AD9) * (Z9/AD9 - 1)^2)) + 1 / (2 * AB9 * ((Z9/AD9) - 1) / (Z9/AD9)^2) ) | AH9: =0.875 * 2 * AB9 * AD9 / Z9 | AI9: ='Input Data'!$C$30 * 'Input Data'!$C$57 * 'Well Profile'!D10 / 1000000 | AJ9: ='Input Data'!$C$47 * ( (Z9/1000)^2 / ( (IF(I9="cased",'Input Data'!$C$20,'Input Data'!$C$19)/1000)^2 - (Z9/1000)^2 ) + 0.4 ) | AK9: =12 * ('Input Data'!$C$31/1000) * AJ9 / (AF9*2)^2 + 6 * 'Input Data'!$C$32 / (AF9*2) | AL9: =AL8+AK9*E9/1000000 | AM9: =AI9+AL9 | AN9: =AM9*1000000/('Input Data'!$C$57*'Well Profile'!D10) | AO9: ='Input Data'!$C$58/AN9 | AP9: =SQRT(((Q9+P9)*9810/(PI()*(Z9^2-AA9^2)/4))^2 + ('Input Data'!$C$59*Z9/(2*AD9))^2 + (-( 'Input Data'!$C$59 + 2*AI9 ) / 2)^2 - ((Q9+P9)*9810/(PI()*(Z9^2-AA9^2)/4))*('Input Data'!$C$59*Z9/(2*AD9)) - ('Input Data'!$C$59*Z9/(2*AD9))*(-( 'Input Data'!$C$59 + 2*AI9 ) / 2) - (-( 'Input Data'!$C$59 + 2*AI9 ) / 2)*((Q9+P9)*9810/(PI()*(Z9^2-AA9^2)/4))) | AQ9: =AB9/AP9 | AR9: =AG9/AI9 | AS9: =AH9/30
B10: 6 | C10: ='Well Profile'!C10 | D10: ='Well Profile'!C11 | E10: =D10-C10 | F10: ='Well Profile'!E10 | G10: ='Well Profile'!E11 | H10: =(F10+G10)/2 | I10: =IF(C10<'Input Data'!$C$21,"cased","open") | J10: =IF(I10="cased",'Input Data'!$C$38,'Input Data'!$C$39) | K10: =AC10*E10/1000 | L10: =K10*'Input Data'!$C$50 | M10: =L10*COS(RADIANS(H10)) | N10: =SQRT((L10*SIN(RADIANS(H10)))^2 + (Q10*ABS(G10-F10)*PI()/180)^2) | O10: =N10*J10 | P10: =O10+P11 | Q10: =M10+Q11 | R10: =Q10-P10+'Input Data'!$C$43 | S10: =Q10+P10+'Input Data'!$C$43 | T10: ='Input Data'!$C$45 - Q11 + P11 | U10: =IF(H10<1, 1.94*(('Input Data'!$C$52*AE10*('Input Data'!$C$54^2))^(1/3))/('Input Data'!$C$57*1000), 2*SQRT('Input Data'!$C$52*AE10*'Input Data'!$C$54*SIN(RADIANS(H10))/AF10)/('Input Data'!$C$57*1000)) | V10: =2*U10 | W10: =IFERROR(IF(T10>0,T10/V10,0),0) | X10: ='Input Data'!$C$33+'Input Data'!$C$34*((C10+D10)/2)/100 | Y10: =IF(W10>1,"DANGER: Helical Buckling",IF(W10>0.5,"Warning: Sinusoidal Buckling",IF(AO10<1,"DANGER: Fracture (ECD Limit)",IF(AR10<1.15,"DANGER: Casing Collapse",IF(AS10<1.1,"DANGER: Casing Burst",IF(AQ10<1.25,"DANGER: Yield Stress",IF(ROW()=5,IF(S10>'Input Data'!$C$44,"Overpull Limit Exceeded",IF(R10<'Input Data'!$C$43,"Slack-off Required",IF(R10>'Input Data'!$C$42,"Rig Capacity Exceeded","Normal"))),"Normal"))))))) | Z10: =LOOKUP((C10+D10)/2, 'Input Data'!$H$5:$H$7, 'Input Data'!$J$5:$J$7) | AA10: =LOOKUP((C10+D10)/2, 'Input Data'!$H$5:$H$7, 'Input Data'!$K$5:$K$7) | AB10: =LOOKUP((C10+D10)/2, 'Input Data'!$H$5:$H$7, 'Input Data'!$M$5:$M$7) | AC10: =LOOKUP((C10+D10)/2, 'Input Data'!$H$5:$H$7, 'Input Data'!$N$5:$N$7) | AD10: =(Z10-AA10)/2 | AE10: =PI()/64*((Z10/1000)^4-(AA10/1000)^4) | AF10: =(IF(I10="cased", 'Input Data'!$C$20, 'Input Data'!$C$19)-Z10)/2000 | AG10: =1 / ( 1 / (2 * ('Input Data'!$C$14 * 1000) / 0.91 / ((Z10/AD10) * (Z10/AD10 - 1)^2)) + 1 / (2 * AB10 * ((Z10/AD10) - 1) / (Z10/AD10)^2) ) | AH10: =0.875 * 2 * AB10 * AD10 / Z10 | AI10: ='Input Data'!$C$30 * 'Input Data'!$C$57 * 'Well Profile'!D11 / 1000000 | AJ10: ='Input Data'!$C$47 * ( (Z10/1000)^2 / ( (IF(I10="cased",'Input Data'!$C$20,'Input Data'!$C$19)/1000)^2 - (Z10/1000)^2 ) + 0.4 ) | AK10: =12 * ('Input Data'!$C$31/1000) * AJ10 / (AF10*2)^2 + 6 * 'Input Data'!$C$32 / (AF10*2) | AL10: =AL9+AK10*E10/1000000 | AM10: =AI10+AL10 | AN10: =AM10*1000000/('Input Data'!$C$57*'Well Profile'!D11) | AO10: ='Input Data'!$C$58/AN10 | AP10: =SQRT(((Q10+P10)*9810/(PI()*(Z10^2-AA10^2)/4))^2 + ('Input Data'!$C$59*Z10/(2*AD10))^2 + (-( 'Input Data'!$C$59 + 2*AI10 ) / 2)^2 - ((Q10+P10)*9810/(PI()*(Z10^2-AA10^2)/4))*('Input Data'!$C$59*Z10/(2*AD10)) - ('Input Data'!$C$59*Z10/(2*AD10))*(-( 'Input Data'!$C$59 + 2*AI10 ) / 2) - (-( 'Input Data'!$C$59 + 2*AI10 ) / 2)*((Q10+P10)*9810/(PI()*(Z10^2-AA10^2)/4))) | AQ10: =AB10/AP10 | AR10: =AG10/AI10 | AS10: =AH10/30
B11: 7 | C11: ='Well Profile'!C11 | D11: ='Well Profile'!C12 | E11: =D11-C11 | F11: ='Well Profile'!E11 | G11: ='Well Profile'!E12 | H11: =(F11+G11)/2 | I11: =IF(C11<'Input Data'!$C$21,"cased","open") | J11: =IF(I11="cased",'Input Data'!$C$38,'Input Data'!$C$39) | K11: =AC11*E11/1000 | L11: =K11*'Input Data'!$C$50 | M11: =L11*COS(RADIANS(H11)) | N11: =SQRT((L11*SIN(RADIANS(H11)))^2 + (Q11*ABS(G11-F11)*PI()/180)^2) | O11: =N11*J11 | P11: =O11+P12 | Q11: =M11+Q12 | R11: =Q11-P11+'Input Data'!$C$43 | S11: =Q11+P11+'Input Data'!$C$43 | T11: ='Input Data'!$C$45 - Q12 + P12 | U11: =IF(H11<1, 1.94*(('Input Data'!$C$52*AE11*('Input Data'!$C$54^2))^(1/3))/('Input Data'!$C$57*1000), 2*SQRT('Input Data'!$C$52*AE11*'Input Data'!$C$54*SIN(RADIANS(H11))/AF11)/('Input Data'!$C$57*1000)) | V11: =2*U11 | W11: =IFERROR(IF(T11>0,T11/V11,0),0) | X11: ='Input Data'!$C$33+'Input Data'!$C$34*((C11+D11)/2)/100 | Y11: =IF(W11>1,"DANGER: Helical Buckling",IF(W11>0.5,"Warning: Sinusoidal Buckling",IF(AO11<1,"DANGER: Fracture (ECD Limit)",IF(AR11<1.15,"DANGER: Casing Collapse",IF(AS11<1.1,"DANGER: Casing Burst",IF(AQ11<1.25,"DANGER: Yield Stress",IF(ROW()=5,IF(S11>'Input Data'!$C$44,"Overpull Limit Exceeded",IF(R11<'Input Data'!$C$43,"Slack-off Required",IF(R11>'Input Data'!$C$42,"Rig Capacity Exceeded","Normal"))),"Normal"))))))) | Z11: =LOOKUP((C11+D11)/2, 'Input Data'!$H$5:$H$7, 'Input Data'!$J$5:$J$7) | AA11: =LOOKUP((C11+D11)/2, 'Input Data'!$H$5:$H$7, 'Input Data'!$K$5:$K$7) | AB11: =LOOKUP((C11+D11)/2, 'Input Data'!$H$5:$H$7, 'Input Data'!$M$5:$M$7) | AC11: =LOOKUP((C11+D11)/2, 'Input Data'!$H$5:$H$7, 'Input Data'!$N$5:$N$7) | AD11: =(Z11-AA11)/2 | AE11: =PI()/64*((Z11/1000)^4-(AA11/1000)^4) | AF11: =(IF(I11="cased", 'Input Data'!$C$20, 'Input Data'!$C$19)-Z11)/2000 | AG11: =1 / ( 1 / (2 * ('Input Data'!$C$14 * 1000) / 0.91 / ((Z11/AD11) * (Z11/AD11 - 1)^2)) + 1 / (2 * AB11 * ((Z11/AD11) - 1) / (Z11/AD11)^2) ) | AH11: =0.875 * 2 * AB11 * AD11 / Z11 | AI11: ='Input Data'!$C$30 * 'Input Data'!$C$57 * 'Well Profile'!D12 / 1000000 | AJ11: ='Input Data'!$C$47 * ( (Z11/1000)^2 / ( (IF(I11="cased",'Input Data'!$C$20,'Input Data'!$C$19)/1000)^2 - (Z11/1000)^2 ) + 0.4 ) | AK11: =12 * ('Input Data'!$C$31/1000) * AJ11 / (AF11*2)^2 + 6 * 'Input Data'!$C$32 / (AF11*2) | AL11: =AL10+AK11*E11/1000000 | AM11: =AI11+AL11 | AN11: =AM11*1000000/('Input Data'!$C$57*'Well Profile'!D12) | AO11: ='Input Data'!$C$58/AN11 | AP11: =SQRT(((Q11+P11)*9810/(PI()*(Z11^2-AA11^2)/4))^2 + ('Input Data'!$C$59*Z11/(2*AD11))^2 + (-( 'Input Data'!$C$59 + 2*AI11 ) / 2)^2 - ((Q11+P11)*9810/(PI()*(Z11^2-AA11^2)/4))*('Input Data'!$C$59*Z11/(2*AD11)) - ('Input Data'!$C$59*Z11/(2*AD11))*(-( 'Input Data'!$C$59 + 2*AI11 ) / 2) - (-( 'Input Data'!$C$59 + 2*AI11 ) / 2)*((Q11+P11)*9810/(PI()*(Z11^2-AA11^2)/4))) | AQ11: =AB11/AP11 | AR11: =AG11/AI11 | AS11: =AH11/30
B12: 8 | C12: ='Well Profile'!C12 | D12: ='Well Profile'!C13 | E12: =D12-C12 | F12: ='Well Profile'!E12 | G12: ='Well Profile'!E13 | H12: =(F12+G12)/2 | I12: =IF(C12<'Input Data'!$C$21,"cased","open") | J12: =IF(I12="cased",'Input Data'!$C$38,'Input Data'!$C$39) | K12: =AC12*E12/1000 | L12: =K12*'Input Data'!$C$50 | M12: =L12*COS(RADIANS(H12)) | N12: =SQRT((L12*SIN(RADIANS(H12)))^2 + (Q12*ABS(G12-F12)*PI()/180)^2) | O12: =N12*J12 | P12: =O12+P13 | Q12: =M12+Q13 | R12: =Q12-P12+'Input Data'!$C$43 | S12: =Q12+P12+'Input Data'!$C$43 | T12: ='Input Data'!$C$45 - Q13 + P13 | U12: =IF(H12<1, 1.94*(('Input Data'!$C$52*AE12*('Input Data'!$C$54^2))^(1/3))/('Input Data'!$C$57*1000), 2*SQRT('Input Data'!$C$52*AE12*'Input Data'!$C$54*SIN(RADIANS(H12))/AF12)/('Input Data'!$C$57*1000)) | V12: =2*U12 | W12: =IFERROR(IF(T12>0,T12/V12,0),0) | X12: ='Input Data'!$C$33+'Input Data'!$C$34*((C12+D12)/2)/100 | Y12: =IF(W12>1,"DANGER: Helical Buckling",IF(W12>0.5,"Warning: Sinusoidal Buckling",IF(AO12<1,"DANGER: Fracture (ECD Limit)",IF(AR12<1.15,"DANGER: Casing Collapse",IF(AS12<1.1,"DANGER: Casing Burst",IF(AQ12<1.25,"DANGER: Yield Stress",IF(ROW()=5,IF(S12>'Input Data'!$C$44,"Overpull Limit Exceeded",IF(R12<'Input Data'!$C$43,"Slack-off Required",IF(R12>'Input Data'!$C$42,"Rig Capacity Exceeded","Normal"))),"Normal"))))))) | Z12: =LOOKUP((C12+D12)/2, 'Input Data'!$H$5:$H$7, 'Input Data'!$J$5:$J$7) | AA12: =LOOKUP((C12+D12)/2, 'Input Data'!$H$5:$H$7, 'Input Data'!$K$5:$K$7) | AB12: =LOOKUP((C12+D12)/2, 'Input Data'!$H$5:$H$7, 'Input Data'!$M$5:$M$7) | AC12: =LOOKUP((C12+D12)/2, 'Input Data'!$H$5:$H$7, 'Input Data'!$N$5:$N$7) | AD12: =(Z12-AA12)/2 | AE12: =PI()/64*((Z12/1000)^4-(AA12/1000)^4) | AF12: =(IF(I12="cased", 'Input Data'!$C$20, 'Input Data'!$C$19)-Z12)/2000 | AG12: =1 / ( 1 / (2 * ('Input Data'!$C$14 * 1000) / 0.91 / ((Z12/AD12) * (Z12/AD12 - 1)^2)) + 1 / (2 * AB12 * ((Z12/AD12) - 1) / (Z12/AD12)^2) ) | AH12: =0.875 * 2 * AB12 * AD12 / Z12 | AI12: ='Input Data'!$C$30 * 'Input Data'!$C$57 * 'Well Profile'!D13 / 1000000 | AJ12: ='Input Data'!$C$47 * ( (Z12/1000)^2 / ( (IF(I12="cased",'Input Data'!$C$20,'Input Data'!$C$19)/1000)^2 - (Z12/1000)^2 ) + 0.4 ) | AK12: =12 * ('Input Data'!$C$31/1000) * AJ12 / (AF12*2)^2 + 6 * 'Input Data'!$C$32 / (AF12*2) | AL12: =AL11+AK12*E12/1000000 | AM12: =AI12+AL12 | AN12: =AM12*1000000/('Input Data'!$C$57*'Well Profile'!D13) | AO12: ='Input Data'!$C$58/AN12 | AP12: =SQRT(((Q12+P12)*9810/(PI()*(Z12^2-AA12^2)/4))^2 + ('Input Data'!$C$59*Z12/(2*AD12))^2 + (-( 'Input Data'!$C$59 + 2*AI12 ) / 2)^2 - ((Q12+P12)*9810/(PI()*(Z12^2-AA12^2)/4))*('Input Data'!$C$59*Z12/(2*AD12)) - ('Input Data'!$C$59*Z12/(2*AD12))*(-( 'Input Data'!$C$59 + 2*AI12 ) / 2) - (-( 'Input Data'!$C$59 + 2*AI12 ) / 2)*((Q12+P12)*9810/(PI()*(Z12^2-AA12^2)/4))) | AQ12: =AB12/AP12 | AR12: =AG12/AI12 | AS12: =AH12/30
B13: 9 | C13: ='Well Profile'!C13 | D13: ='Well Profile'!C14 | E13: =D13-C13 | F13: ='Well Profile'!E13 | G13: ='Well Profile'!E14 | H13: =(F13+G13)/2 | I13: =IF(C13<'Input Data'!$C$21,"cased","open") | J13: =IF(I13="cased",'Input Data'!$C$38,'Input Data'!$C$39) | K13: =AC13*E13/1000 | L13: =K13*'Input Data'!$C$50 | M13: =L13*COS(RADIANS(H13)) | N13: =SQRT((L13*SIN(RADIANS(H13)))^2 + (Q13*ABS(G13-F13)*PI()/180)^2) | O13: =N13*J13 | P13: =O13+P14 | Q13: =M13+Q14 | R13: =Q13-P13+'Input Data'!$C$43 | S13: =Q13+P13+'Input Data'!$C$43 | T13: ='Input Data'!$C$45 - Q14 + P14 | U13: =IF(H13<1, 1.94*(('Input Data'!$C$52*AE13*('Input Data'!$C$54^2))^(1/3))/('Input Data'!$C$57*1000), 2*SQRT('Input Data'!$C$52*AE13*'Input Data'!$C$54*SIN(RADIANS(H13))/AF13)/('Input Data'!$C$57*1000)) | V13: =2*U13 | W13: =IFERROR(IF(T13>0,T13/V13,0),0) | X13: ='Input Data'!$C$33+'Input Data'!$C$34*((C13+D13)/2)/100 | Y13: =IF(W13>1,"DANGER: Helical Buckling",IF(W13>0.5,"Warning: Sinusoidal Buckling",IF(AO13<1,"DANGER: Fracture (ECD Limit)",IF(AR13<1.15,"DANGER: Casing Collapse",IF(AS13<1.1,"DANGER: Casing Burst",IF(AQ13<1.25,"DANGER: Yield Stress",IF(ROW()=5,IF(S13>'Input Data'!$C$44,"Overpull Limit Exceeded",IF(R13<'Input Data'!$C$43,"Slack-off Required",IF(R13>'Input Data'!$C$42,"Rig Capacity Exceeded","Normal"))),"Normal"))))))) | Z13: =LOOKUP((C13+D13)/2, 'Input Data'!$H$5:$H$7, 'Input Data'!$J$5:$J$7) | AA13: =LOOKUP((C13+D13)/2, 'Input Data'!$H$5:$H$7, 'Input Data'!$K$5:$K$7) | AB13: =LOOKUP((C13+D13)/2, 'Input Data'!$H$5:$H$7, 'Input Data'!$M$5:$M$7) | AC13: =LOOKUP((C13+D13)/2, 'Input Data'!$H$5:$H$7, 'Input Data'!$N$5:$N$7) | AD13: =(Z13-AA13)/2 | AE13: =PI()/64*((Z13/1000)^4-(AA13/1000)^4) | AF13: =(IF(I13="cased", 'Input Data'!$C$20, 'Input Data'!$C$19)-Z13)/2000 | AG13: =1 / ( 1 / (2 * ('Input Data'!$C$14 * 1000) / 0.91 / ((Z13/AD13) * (Z13/AD13 - 1)^2)) + 1 / (2 * AB13 * ((Z13/AD13) - 1) / (Z13/AD13)^2) ) | AH13: =0.875 * 2 * AB13 * AD13 / Z13 | AI13: ='Input Data'!$C$30 * 'Input Data'!$C$57 * 'Well Profile'!D14 / 1000000 | AJ13: ='Input Data'!$C$47 * ( (Z13/1000)^2 / ( (IF(I13="cased",'Input Data'!$C$20,'Input Data'!$C$19)/1000)^2 - (Z13/1000)^2 ) + 0.4 ) | AK13: =12 * ('Input Data'!$C$31/1000) * AJ13 / (AF13*2)^2 + 6 * 'Input Data'!$C$32 / (AF13*2) | AL13: =AL12+AK13*E13/1000000 | AM13: =AI13+AL13 | AN13: =AM13*1000000/('Input Data'!$C$57*'Well Profile'!D14) | AO13: ='Input Data'!$C$58/AN13 | AP13: =SQRT(((Q13+P13)*9810/(PI()*(Z13^2-AA13^2)/4))^2 + ('Input Data'!$C$59*Z13/(2*AD13))^2 + (-( 'Input Data'!$C$59 + 2*AI13 ) / 2)^2 - ((Q13+P13)*9810/(PI()*(Z13^2-AA13^2)/4))*('Input Data'!$C$59*Z13/(2*AD13)) - ('Input Data'!$C$59*Z13/(2*AD13))*(-( 'Input Data'!$C$59 + 2*AI13 ) / 2) - (-( 'Input Data'!$C$59 + 2*AI13 ) / 2)*((Q13+P13)*9810/(PI()*(Z13^2-AA13^2)/4))) | AQ13: =AB13/AP13 | AR13: =AG13/AI13 | AS13: =AH13/30
B14: 10 | C14: ='Well Profile'!C14 | D14: ='Well Profile'!C15 | E14: =D14-C14 | F14: ='Well Profile'!E14 | G14: ='Well Profile'!E15 | H14: =(F14+G14)/2 | I14: =IF(C14<'Input Data'!$C$21,"cased","open") | J14: =IF(I14="cased",'Input Data'!$C$38,'Input Data'!$C$39) | K14: =AC14*E14/1000 | L14: =K14*'Input Data'!$C$50 | M14: =L14*COS(RADIANS(H14)) | N14: =SQRT((L14*SIN(RADIANS(H14)))^2 + (Q14*ABS(G14-F14)*PI()/180)^2) | O14: =N14*J14 | P14: =O14 | Q14: =M14 | R14: =Q14-P14+'Input Data'!$C$43 | S14: =Q14+P14+'Input Data'!$C$43 | T14: ='Input Data'!$C$45 - Q15 + P15 | U14: =IF(H14<1, 1.94*(('Input Data'!$C$52*AE14*('Input Data'!$C$54^2))^(1/3))/('Input Data'!$C$57*1000), 2*SQRT('Input Data'!$C$52*AE14*'Input Data'!$C$54*SIN(RADIANS(H14))/AF14)/('Input Data'!$C$57*1000)) | V14: =2*U14 | W14: =IFERROR(IF(T14>0,T14/V14,0),0) | X14: ='Input Data'!$C$33+'Input Data'!$C$34*((C14+D14)/2)/100 | Y14: =IF(W14>1,"DANGER: Helical Buckling",IF(W14>0.5,"Warning: Sinusoidal Buckling",IF(AO14<1,"DANGER: Fracture (ECD Limit)",IF(AR14<1.15,"DANGER: Casing Collapse",IF(AS14<1.1,"DANGER: Casing Burst",IF(AQ14<1.25,"DANGER: Yield Stress",IF(ROW()=5,IF(S14>'Input Data'!$C$44,"Overpull Limit Exceeded",IF(R14<'Input Data'!$C$43,"Slack-off Required",IF(R14>'Input Data'!$C$42,"Rig Capacity Exceeded","Normal"))),"Normal"))))))) | Z14: =LOOKUP((C14+D14)/2, 'Input Data'!$H$5:$H$7, 'Input Data'!$J$5:$J$7) | AA14: =LOOKUP((C14+D14)/2, 'Input Data'!$H$5:$H$7, 'Input Data'!$K$5:$K$7) | AB14: =LOOKUP((C14+D14)/2, 'Input Data'!$H$5:$H$7, 'Input Data'!$M$5:$M$7) | AC14: =LOOKUP((C14+D14)/2, 'Input Data'!$H$5:$H$7, 'Input Data'!$N$5:$N$7) | AD14: =(Z14-AA14)/2 | AE14: =PI()/64*((Z14/1000)^4-(AA14/1000)^4) | AF14: =(IF(I14="cased", 'Input Data'!$C$20, 'Input Data'!$C$19)-Z14)/2000 | AG14: =1 / ( 1 / (2 * ('Input Data'!$C$14 * 1000) / 0.91 / ((Z14/AD14) * (Z14/AD14 - 1)^2)) + 1 / (2 * AB14 * ((Z14/AD14) - 1) / (Z14/AD14)^2) ) | AH14: =0.875 * 2 * AB14 * AD14 / Z14 | AI14: ='Input Data'!$C$30 * 'Input Data'!$C$57 * 'Well Profile'!D15 / 1000000 | AJ14: ='Input Data'!$C$47 * ( (Z14/1000)^2 / ( (IF(I14="cased",'Input Data'!$C$20,'Input Data'!$C$19)/1000)^2 - (Z14/1000)^2 ) + 0.4 ) | AK14: =12 * ('Input Data'!$C$31/1000) * AJ14 / (AF14*2)^2 + 6 * 'Input Data'!$C$32 / (AF14*2) | AL14: =AL13+AK14*E14/1000000 | AM14: =AI14+AL14 | AN14: =AM14*1000000/('Input Data'!$C$57*'Well Profile'!D15) | AO14: ='Input Data'!$C$58/AN14 | AP14: =SQRT(((Q14+P14)*9810/(PI()*(Z14^2-AA14^2)/4))^2 + ('Input Data'!$C$59*Z14/(2*AD14))^2 + (-( 'Input Data'!$C$59 + 2*AI14 ) / 2)^2 - ((Q14+P14)*9810/(PI()*(Z14^2-AA14^2)/4))*('Input Data'!$C$59*Z14/(2*AD14)) - ('Input Data'!$C$59*Z14/(2*AD14))*(-( 'Input Data'!$C$59 + 2*AI14 ) / 2) - (-( 'Input Data'!$C$59 + 2*AI14 ) / 2)*((Q14+P14)*9810/(PI()*(Z14^2-AA14^2)/4))) | AQ14: =AB14/AP14 | AR14: =AG14/AI14 | AS14: =AH14/30

Sheet Charts
B2: CHARTS AND VISUALIZATION
B3: All charts are plotted using data from the "Calculations" sheet. Updated automatically.
B4: MD, m | C4: Rig Capacity, t | D4: Max Overpull, t | E4: Max Slack-off, t | F4: Block Weight, t
B5: =Calculations!C5 | C5: ='Input Data'!$C$42 | D5: ='Input Data'!$C$44 | E5: ='Input Data'!$C$45 | F5: ='Input Data'!$C$43
B6: =Calculations!C6 | C6: ='Input Data'!$C$42 | D6: ='Input Data'!$C$44 | E6: ='Input Data'!$C$45 | F6: ='Input Data'!$C$43
B7: =Calculations!C7 | C7: ='Input Data'!$C$42 | D7: ='Input Data'!$C$44 | E7: ='Input Data'!$C$45 | F7: ='Input Data'!$C$43
B8: =Calculations!C8 | C8: ='Input Data'!$C$42 | D8: ='Input Data'!$C$44 | E8: ='Input Data'!$C$45 | F8: ='Input Data'!$C$43
B9: =Calculations!C9 | C9: ='Input Data'!$C$42 | D9: ='Input Data'!$C$44 | E9: ='Input Data'!$C$45 | F9: ='Input Data'!$C$43
B10: =Calculations!C10 | C10: ='Input Data'!$C$42 | D10: ='Input Data'!$C$44 | E10: ='Input Data'!$C$45 | F10: ='Input Data'!$C$43
B11: =Calculations!C11 | C11: ='Input Data'!$C$42 | D11: ='Input Data'!$C$44 | E11: ='Input Data'!$C$45 | F11: ='Input Data'!$C$43
B12: =Calculations!C12 | C12: ='Input Data'!$C$42 | D12: ='Input Data'!$C$44 | E12: ='Input Data'!$C$45 | F12: ='Input Data'!$C$43
B13: =Calculations!C13 | C13: ='Input Data'!$C$42 | D13: ='Input Data'!$C$44 | E13: ='Input Data'!$C$45 | F13: ='Input Data'!$C$43
B14: =Calculations!C14 | C14: ='Input Data'!$C$42 | D14: ='Input Data'!$C$44 | E14: ='Input Data'!$C$45 | F14: ='Input Data'!$C$43

Sheet Summary
B2: SUMMARY AND CASING RUNNING RECOMMENDATIONS
B4: 1. Key Performance Indicators and Casing Integrity (KPI)
B5: KPI Parameter | C5: Value | D5: Unit | E5: Margin / Constraint | F5: Safety Status
B6: Maximum Tension Load (POOH) | C6: =MAX(Calculations!S5:S14) | D6: t | E6: ="Limit: " & 'Input Data'!$C$44 & " t" | F6: =IF(C6>'Input Data'!$C$44, "CRITICAL RISK", IF(C6>'Input Data'!$C$42/'Input Data'!$C$46, "Warning: close to limit", "Normal"))
B7: Minimum Running Hook Load (RIH) | C7: =MIN(Calculations!R5:R14) | D7: t | E7: ="Block weight: " & 'Input Data'!$C$43 & " t" | F7: =IF(C7<'Input Data'!$C$43, "Weight transfer to hole bottom", "Normal")
B8: Maximum Buckling Factor | C8: =MAX(Calculations!W5:W14) | D8: — | E8: Предел: 1.00 | F8: =IF(C8>1, "CRITICAL RISK: Helical Buckling", IF(C8>0.5, "Warning: Sinusoidal Buckling", "Normal"))
B9: Maximum Equivalent Circulating Density (ECD) | C9: =MAX(Calculations!AN5:AN14) | D9: kg/m³ | E9: ="Losses limit: " & 'Input Data'!$C$58 & " кг/м³" | F9: =IF(C9>'Input Data'!$C$58, "CRITICAL RISK: Mud Losses", "Normal")
B10: Minimum ECD Safety Factor | C10: =MIN(Calculations!AO5:AO14) | D10: — | E10: Норматив: 1.05 | F10: =IF(C10<1, "EMERGENCY: Mud Losses", IF(C10<1.05, "Warning: losses risk", "Normal"))
B11: Minimum Collapse Safety Factor | C11: =MIN(Calculations!AR5:AR14) | D11: — | E11: Normative: 1.15 | F11: =IF(C11<1, "EMERGENCY: Collapse Risk", IF(C11<1.15, "Warning: low safety factor", "Normal"))
B12: Minimum Burst Safety Factor | C12: =MIN(Calculations!AS5:AS14) | D12: — | E12: Normative: 1.10 | F12: =IF(C12<1, "EMERGENCY: Burst Risk", IF(C12<1.1, "Warning: low safety factor", "Normal"))
B13: Minimum von Mises Safety Factor | C13: =MIN(Calculations!AQ5:AQ14) | D13: — | E13: Normative: 1.25 | F13: =IF(C13<1, "EMERGENCY: Casing Yielding", IF(C13<1.25, "Warning: low safety factor", "Normal"))
B14: Maximum Surge Pressure | C14: =MAX(Calculations!AL5:AL14) | D14: MPa | E14: Reference | F14: =""
B15: Maximum Wellbore Temperature | C15: =MAX(Calculations!X5:X14) | D15: °C | E15: Fluid limit: 120 °C | F15: =IF(C15>120, "Внимание: деструкция раствора", "Normal")
B16: Number of Hazardous Intervals | F16: =IF(C16>0, "Warning: mitigation required", "Normal")
B18: 2. Identified Hazardous Intervals (Requiring Action)
B19: No. | C19: Depth Interval MD, m | D19: Hole Type | E19: Hazard Type / Status | F19: Engineering Indicator
B20: =IF(Calculations!Y5<>"Normal",Calculations!B5,"") | C20: =IF(Calculations!Y5<>"Normal",Calculations!C5&" - "&Calculations!D5,"") | D20: =IF(Calculations!Y5<>"Normal",IF(Calculations!I5="cased","Cased","Open"),"") | E20: =IF(Calculations!Y5<>"Normal",Calculations!Y5,"") | F20: =IF(Calculations!Y5<>"Normal",IF(Calculations!W5>0.5,TEXT(Calculations!W5,"0.00")&" (buckling)",IF(Calculations!AO5<1.05,TEXT(Calculations!AN5,"0")&" kg/m³ (ECD)",IF(Calculations!AR5<1.15,TEXT(Calculations!AR5,"0.00")&" (SF_collapse)",IF(Calculations!AS5<1.1,TEXT(Calculations!AS5,"0.00")&" (SF_burst)",IF(Calculations!AQ5<1.25,TEXT(Calculations!AQ5,"0.00")&" (SF_strength)",TEXT(Calculations!S5,"0")&" t (load)"))))),"")
B21: =IF(Calculations!Y6<>"Normal",Calculations!B6,"") | C21: =IF(Calculations!Y6<>"Normal",Calculations!C6&" - "&Calculations!D6,"") | D21: =IF(Calculations!Y6<>"Normal",IF(Calculations!I6="cased","Cased","Open"),"") | E21: =IF(Calculations!Y6<>"Normal",Calculations!Y6,"") | F21: =IF(Calculations!Y6<>"Normal",IF(Calculations!W6>0.5,TEXT(Calculations!W6,"0.00")&" (buckling)",IF(Calculations!AO6<1.05,TEXT(Calculations!AN6,"0")&" kg/m³ (ECD)",IF(Calculations!AR6<1.15,TEXT(Calculations!AR6,"0.00")&" (SF_collapse)",IF(Calculations!AS6<1.1,TEXT(Calculations!AS6,"0.00")&" (SF_burst)",IF(Calculations!AQ6<1.25,TEXT(Calculations!AQ6,"0.00")&" (SF_strength)",TEXT(Calculations!S6,"0")&" t (load)"))))),"")
B22: =IF(Calculations!Y7<>"Normal",Calculations!B7,"") | C22: =IF(Calculations!Y7<>"Normal",Calculations!C7&" - "&Calculations!D7,"") | D22: =IF(Calculations!Y7<>"Normal",IF(Calculations!I7="cased","Cased","Open"),"") | E22: =IF(Calculations!Y7<>"Normal",Calculations!Y7,"") | F22: =IF(Calculations!Y7<>"Normal",IF(Calculations!W7>0.5,TEXT(Calculations!W7,"0.00")&" (buckling)",IF(Calculations!AO7<1.05,TEXT(Calculations!AN7,"0")&" kg/m³ (ECD)",IF(Calculations!AR7<1.15,TEXT(Calculations!AR7,"0.00")&" (SF_collapse)",IF(Calculations!AS7<1.1,TEXT(Calculations!AS7,"0.00")&" (SF_burst)",IF(Calculations!AQ7<1.25,TEXT(Calculations!AQ7,"0.00")&" (SF_strength)",TEXT(Calculations!S7,"0")&" t (load)"))))),"")
B23: =IF(Calculations!Y8<>"Normal",Calculations!B8,"") | C23: =IF(Calculations!Y8<>"Normal",Calculations!C8&" - "&Calculations!D8,"") | D23: =IF(Calculations!Y8<>"Normal",IF(Calculations!I8="cased","Cased","Open"),"") | E23: =IF(Calculations!Y8<>"Normal",Calculations!Y8,"") | F23: =IF(Calculations!Y8<>"Normal",IF(Calculations!W8>0.5,TEXT(Calculations!W8,"0.00")&" (buckling)",IF(Calculations!AO8<1.05,TEXT(Calculations!AN8,"0")&" kg/m³ (ECD)",IF(Calculations!AR8<1.15,TEXT(Calculations!AR8,"0.00")&" (SF_collapse)",IF(Calculations!AS8<1.1,TEXT(Calculations!AS8,"0.00")&" (SF_burst)",IF(Calculations!AQ8<1.25,TEXT(Calculations!AQ8,"0.00")&" (SF_strength)",TEXT(Calculations!S8,"0")&" t (load)"))))),"")
B24: =IF(Calculations!Y9<>"Normal",Calculations!B9,"") | C24: =IF(Calculations!Y9<>"Normal",Calculations!C9&" - "&Calculations!D9,"") | D24: =IF(Calculations!Y9<>"Normal",IF(Calculations!I9="cased","Cased","Open"),"") | E24: =IF(Calculations!Y9<>"Normal",Calculations!Y9,"") | F24: =IF(Calculations!Y9<>"Normal",IF(Calculations!W9>0.5,TEXT(Calculations!W9,"0.00")&" (buckling)",IF(Calculations!AO9<1.05,TEXT(Calculations!AN9,"0")&" kg/m³ (ECD)",IF(Calculations!AR9<1.15,TEXT(Calculations!AR9,"0.00")&" (SF_collapse)",IF(Calculations!AS9<1.1,TEXT(Calculations!AS9,"0.00")&" (SF_burst)",IF(Calculations!AQ9<1.25,TEXT(Calculations!AQ9,"0.00")&" (SF_strength)",TEXT(Calculations!S9,"0")&" t (load)"))))),"")
B25: =IF(Calculations!Y10<>"Normal",Calculations!B10,"") | C25: =IF(Calculations!Y10<>"Normal",Calculations!C10&" - "&Calculations!D10,"") | D25: =IF(Calculations!Y10<>"Normal",IF(Calculations!I10="cased","Cased","Open"),"") | E25: =IF(Calculations!Y10<>"Normal",Calculations!Y10,"") | F25: =IF(Calculations!Y10<>"Normal",IF(Calculations!W10>0.5,TEXT(Calculations!W10,"0.00")&" (buckling)",IF(Calculations!AO10<1.05,TEXT(Calculations!AN10,"0")&" kg/m³ (ECD)",IF(Calculations!AR10<1.15,TEXT(Calculations!AR10,"0.00")&" (SF_collapse)",IF(Calculations!AS10<1.1,TEXT(Calculations!AS10,"0.00")&" (SF_burst)",IF(Calculations!AQ10<1.25,TEXT(Calculations!AQ10,"0.00")&" (SF_strength)",TEXT(Calculations!S10,"0")&" t (load)"))))),"")
B26: =IF(Calculations!Y11<>"Normal",Calculations!B11,"") | C26: =IF(Calculations!Y11<>"Normal",Calculations!C11&" - "&Calculations!D11,"") | D26: =IF(Calculations!Y11<>"Normal",IF(Calculations!I11="cased","Cased","Open"),"") | E26: =IF(Calculations!Y11<>"Normal",Calculations!Y11,"") | F26: =IF(Calculations!Y11<>"Normal",IF(Calculations!W11>0.5,TEXT(Calculations!W11,"0.00")&" (buckling)",IF(Calculations!AO11<1.05,TEXT(Calculations!AN11,"0")&" kg/m³ (ECD)",IF(Calculations!AR11<1.15,TEXT(Calculations!AR11,"0.00")&" (SF_collapse)",IF(Calculations!AS11<1.1,TEXT(Calculations!AS11,"0.00")&" (SF_burst)",IF(Calculations!AQ11<1.25,TEXT(Calculations!AQ11,"0.00")&" (SF_strength)",TEXT(Calculations!S11,"0")&" t (load)"))))),"")
B27: =IF(Calculations!Y12<>"Normal",Calculations!B12,"") | C27: =IF(Calculations!Y12<>"Normal",Calculations!C12&" - "&Calculations!D12,"") | D27: =IF(Calculations!Y12<>"Normal",IF(Calculations!I12="cased","Cased","Open"),"") | E27: =IF(Calculations!Y12<>"Normal",Calculations!Y12,"") | F27: =IF(Calculations!Y12<>"Normal",IF(Calculations!W12>0.5,TEXT(Calculations!W12,"0.00")&" (buckling)",IF(Calculations!AO12<1.05,TEXT(Calculations!AN12,"0")&" kg/m³ (ECD)",IF(Calculations!AR12<1.15,TEXT(Calculations!AR12,"0.00")&" (SF_collapse)",IF(Calculations!AS12<1.1,TEXT(Calculations!AS12,"0.00")&" (SF_burst)",IF(Calculations!AQ12<1.25,TEXT(Calculations!AQ12,"0.00")&" (SF_strength)",TEXT(Calculations!S12,"0")&" t (load)"))))),"")
B28: =IF(Calculations!Y13<>"Normal",Calculations!B13,"") | C28: =IF(Calculations!Y13<>"Normal",Calculations!C13&" - "&Calculations!D13,"") | D28: =IF(Calculations!Y13<>"Normal",IF(Calculations!I13="cased","Cased","Open"),"") | E28: =IF(Calculations!Y13<>"Normal",Calculations!Y13,"") | F28: =IF(Calculations!Y13<>"Normal",IF(Calculations!W13>0.5,TEXT(Calculations!W13,"0.00")&" (buckling)",IF(Calculations!AO13<1.05,TEXT(Calculations!AN13,"0")&" kg/m³ (ECD)",IF(Calculations!AR13<1.15,TEXT(Calculations!AR13,"0.00")&" (SF_collapse)",IF(Calculations!AS13<1.1,TEXT(Calculations!AS13,"0.00")&" (SF_burst)",IF(Calculations!AQ13<1.25,TEXT(Calculations!AQ13,"0.00")&" (SF_strength)",TEXT(Calculations!S13,"0")&" t (load)"))))),"")
B29: =IF(Calculations!Y14<>"Normal",Calculations!B14,"") | C29: =IF(Calculations!Y14<>"Normal",Calculations!C14&" - "&Calculations!D14,"") | D29: =IF(Calculations!Y14<>"Normal",IF(Calculations!I14="cased","Cased","Open"),"") | E29: =IF(Calculations!Y14<>"Normal",Calculations!Y14,"") | F29: =IF(Calculations!Y14<>"Normal",IF(Calculations!W14>0.5,TEXT(Calculations!W14,"0.00")&" (buckling)",IF(Calculations!AO14<1.05,TEXT(Calculations!AN14,"0")&" kg/m³ (ECD)",IF(Calculations!AR14<1.15,TEXT(Calculations!AR14,"0.00")&" (SF_collapse)",IF(Calculations!AS14<1.1,TEXT(Calculations!AS14,"0.00")&" (SF_burst)",IF(Calculations!AQ14<1.25,TEXT(Calculations!AQ14,"0.00")&" (SF_strength)",TEXT(Calculations!S14,"0")&" t (load)"))))),"")
B31: 3. Casing Running Engineering Recommendations
B32: • Drilling Fluid: Monitor density and rheology. If ECD exceeds 1550 kg/m³, reduce casing running speed.
B33: • Running Speed: Maintain in safe limits (≤ 0.5 m/s) to prevent hydraulic fracture and mud losses.
B34: • Buckling Mitigation: Install casing centralizers in KOP/build sections (600-1050 m) and TD sections (3000-3450 m) to reduce drag and prevent lock-up.
B35: • Casing Integrity (Collapse/Burst): Collapse is critical at TD (SF_collapse = 1.05 at 180 t slack-off). Do not exceed allowed compressive loads during slack-off.
B36: • von Mises Stress: At 30 MPa casing pressure test, the strength safety factor is 2.34 (safe). Do not exceed 40 MPa during test.
B37: • Hook Load Monitoring: If overpull exceeds 200 t (limit), stop casing run, work the pipe, and circulate mud.
