Workbook

Sheet Входные данные
B2: КАЛЬКУЛЯТОР СПУСКА ОБСАДНЫХ КОЛОНН — ВХОДНЫЕ ДАННЫЕ
B3: Жёлтые ячейки — для ввода данных. Остальные рассчитываются автоматически.
B4: Параметр | C4: Значение | D4: Ед. изм. | E4: Примечание | G4: Секция № | H4: Top MD, м | I4: Bottom MD, м | J4: OD, мм | K4: ID, мм | L4: Сталь | M4: Yp, МПа | N4: Вес, кг/м
B5: 1. Скважина и обсадная колонна | G5: 1 | H5: 0 | I5: ='Входные данные'!$C$11 -> 3450 | J5: ='Входные данные'!$C$7 -> 244.5 | K5: ='Входные данные'!$C$8 -> 220.5 | L5: ='Входные данные'!$C$12 -> P110 | M5: ='Входные данные'!$C$13 -> 758 | N5: ='Входные данные'!$C$10 -> 69.94
B6: Глубина скважины (TD) | C6: 3800 | D6: м | E6: Проектная глубина | G6: 2 | H6: 99999 | I6: 99999
B7: Наружный диаметр обсадной трубы (OD) | C7: 244.5 | D7: мм | E7: Напр. 9-5/8" = 244.5 мм | G7: 3 | H7: 99999 | I7: 99999
B8: Внутренний диаметр обсадной трубы (ID) | C8: 220.5 | D8: мм | E8: С учётом толщины стенки
B9: Толщина стенки | C9: =($C$7-$C$8)/2 -> 12 | D9: мм | E9: Расчётная
B10: Вес 1 погонного метра колонны | C10: 69.94 | D10: кг/м | E10: Справочное значение
B11: Глубина спуска башмака обсадной колонны | C11: 3450 | D11: м | E11: Обычно ≤ TD
B12: Марка стали | C12: P110 | D12: — | E12: J55/K55/N80/L80/P110 и т.д.
B13: Предел текучести стали | C13: 758 | D13: МПа | E13: Для P110 ≈ 758 МПа
B14: Модуль упругости стали (E) | C14: 210 | D14: ГПа | E14: Сталь ≈ 210 ГПа
B15: Плотность стали | C15: 7850 | D15: кг/м³ | E15: Справочно
B16: Площадь поперечного сечения трубы | C16: =PI()*($C$7^2-$C$8^2)/4 -> 8765.0435 | D16: мм² | E16: Расчётная
B18: 2. Ствол скважины
B19: Диаметр открытого ствола | C19: 311.2 | D19: мм | E19: Напр. 12-1/4" = 311.2 мм
B20: Внутренний диаметр предыдущей колонны | C20: 317.9 | D20: мм | E20: Напр. 13-3/8" = 339.7 мм OD, ID ≈ 317.9
B21: Глубина башмака предыдущей колонны | C21: 1800 | D21: м | E21: Граница обс./откр. ствола
B23: 3. Профиль скважины (инклинометрия)
B24: Точка начала отхода (KOP) | C24: 600 | D24: м | E24: Глубина начала набора угла
B25: Интенсивность набора кривизны | C25: 3 | D25: град/30м | E25: Типовое 2–4 град/30м
B26: Зенитный угол на забое | C26: 45 | D26: град | E26: Макс. угол отклонения от вертикали
B27: Азимут | C27: 90 | D27: град | E27: См. лист «Профиль ствола»
B29: 4. Буровой раствор
B30: Плотность бурового раствора | C30: 1350 | D30: кг/м³ | E30: 1.35 г/см³
B31: Пластическая вязкость (PV) | C31: 25 | D31: сП | E31: Пластическая вязкость
B32: Предельное напряжение сдвига (YP) | C32: 15 | D32: Па | E32: Yield Point
B33: Температура раствора на устье | C33: 20 | D33: °C | E33: Начальная температура
B34: Геотермальный градиент | C34: 3 | D34: °C/100м | E34: Типовое 2.5–3.5
B35: Температура раствора на забое | C35: =$C$33+$C$34*'Профиль ствола'!$D$15/100 -> 100.85 | D35: °C | E35: Расчёт
B37: 5. Коэффициенты трения
B38: Коэффициент трения в обсаженной части (μ_c) | C38: 0.25 | D38: — | E38: Типовое 0.20–0.30
B39: Коэффициент трения в открытом стволе (μ_o) | C39: 0.35 | D39: — | E39: Типовое 0.30–0.45
B41: 6. Оборудование и ограничения
B42: Грузоподъёмность буровой установки | C42: 250 | D42: т | E42: Макс. нагрузка на крюк
B43: Вес талевой системы | C43: 15 | D43: т | E43: Крюкоблок + талевый канат
B44: Максимально допустимая затяжка | C44: 200 | D44: т | E44: Предел натяжения
B45: Максимально допустимая разгрузка | C45: 180 | D45: т | E45: Предел сжатия (slack-off)
B46: Коэффициент запаса прочности | C46: 1.3 | D46: — | E46: По нагрузке
...

Sheet Профиль ствола
B2: ПРОФИЛЬ СТВОЛА СКВАЖИНЫ — ИНКЛИНОМЕТРИЯ
B4: № | C4: MD, м | D4: TVD, м | E4: Зенитный угол, ° | F4: Азимут, ° | G4: Тип секции | H4: DLS, °/30м
B5: 1 | C5: 0 | D5: 0 | E5: 0 | F5: 90 | G5: Вертикальная | H5: 0
B6: 2 | C6: 300 | D6: 300 | E6: 0 | F6: 90 | G6: Вертикальная | H6: =ABS(E6-E5)/(C6-C5)*30 -> 0
B7: 3 | C7: 600 | D7: 600 | E7: 0 | F7: 90 | G7: Вертикальная (KOP) | H7: =ABS(E7-E6)/(C7-C6)*30 -> 0
B8: 4 | C8: 750 | D8: 748 | E8: 15 | F8: 90 | G8: Набор угла | H8: =ABS(E8-E7)/(C8-C7)*30 -> 3
B9: 5 | C9: 900 | D9: 891 | E9: 30 | F9: 90 | G9: Набор угла | H9: =ABS(E9-E8)/(C9-C8)*30 -> 3
B10: 6 | C10: 1050 | D10: 1024 | E10: 45 | F10: 90 | G10: Набор угла (конец) | H10: =ABS(E10-E9)/(C10-C9)*30 -> 3
B11: 7 | C11: 1500 | D11: 1341 | E11: 45 | F11: 90 | G11: Стабилизация | H11: =ABS(E11-E10)/(C11-C10)*30 -> 0
B12: 8 | C12: 2000 | D12: 1694 | E12: 45 | F12: 90 | G12: Стабилизация | H12: =ABS(E12-E11)/(C12-C11)*30 -> 0
B13: 9 | C13: 2500 | D13: 2048 | E13: 45 | F13: 90 | G13: Стабилизация | H13: =ABS(E13-E12)/(C13-C12)*30 -> 0
B14: 10 | C14: 3000 | D14: 2401 | E14: 45 | F14: 90 | G14: Стабилизация | H14: =ABS(E14-E13)/(C14-C13)*30 -> 0
B15: 11 | C15: 3450 | D15: 2695 | E15: 45 | F15: 90 | G15: Стабилизация (TD) | H15: =ABS(E15-E14)/(C15-C14)*30 -> 0

Sheet Расчёт
B2: РАСЧЁТ ВОЗМОЖНОСТИ СПУСКА — ПОИНТЕРВАЛЬНЫЙ АНАЛИЗ
B3: Всего интервалов: 10. Цветом выделены осложнённые интервалы (изгиб/разгрузка/превышение нагрузки). Нагрузка на крюк и накопленные суммы считаются от забоя к устью; сжимающая сила — от устья к забою.
B4: № | C4: MD верх, м | D4: MD низ, м | E4: ΔL, м | F4: Угол верх, ° | G4: Угол низ, ° | H4: Угол средний, ° | I4: Тип ствола | J4: μ | K4: Вес в воздухе, т | L4: Плавучий вес, т | M4: Осевая сост. веса, т | N4: Нормальная сила, т | O4: Сила трения, т | P4: Накопл. трение, т | Q4: Накопл. осев. вес, т | R4: Нагр. на крюк (спуск), т | S4: Нагр. на крюк (подъём), т | T4: Сжимающая сила, т | U4: F_крит синус., т | V4: F_крит спирал., т | W4: Коэф. изгиба | X4: Темп., °C | Y4: Статус | Z4: OD, мм | AA4: ID, мм | AB4: Yp, МПа | AC4: Вес, кг/м | AD4: t, мм | AE4: I, м⁴ | AF4: r, м | AG4: P_coll_res, МПа | AH4: P_burst_res, МПа | AI4: P_hydro, МПа | AJ4: v_ann, м/с | AK4: dP/dz, Па/м | AL4: P_surge, МПа | AM4: P_total, МПа | AN4: ECD, кг/м³ | AO4: SF_ECD | AP4: VM Stress, МПа | AQ4: SF_Strength | AR4: SF_Collapse | AS4: SF_Burst
B5: 1 | C5: ='Профиль ствола'!C5 -> 0 | D5: ='Профиль ствола'!C6 -> 300 | E5: =D5-C5 -> 300 | F5: ='Профиль ствола'!E5 -> 0 | G5: ='Профиль ствола'!E6 -> 0 | H5: =(F5+G5)/2 -> 0 | I5: =IF(C5<'Входные данные'!$C$21,"обс.","откр.") -> обс. | J5: =IF(I5="обс.",'Входные данные'!$C$38,'Входные данные'!$C$39) -> 0.25 | K5: =AC5*E5/1000 -> 20.982 | L5: =K5*'Входные данные'!$C$50 -> 17.373631 | M5: =L5*COS(RADIANS(H5)) -> 17.373631 | N5: =SQRT((L5*SIN(RADIANS(H5)))^2 + (Q5*ABS(G5-F5)*PI()/180)^2) -> 0 | O5: =N5*J5 -> 0 | P5: =O5+P6 -> 52.94976 | Q5: =M5+Q6 -> 156.55714 | R5: =Q5-P5+'Входные данные'!$C$43 -> 118.60738 | S5: =Q5+P5+'Входные данные'!$C$43 -> 224.5069 | T5: ='Входные данные'!$C$45 - Q6 + P6 -> 93.766251 | U5: =IF(H5<1, 1.94*(('Входные данные'!$C$52*AE5*('Входные данные'!$C$54^2))^(1/3))/('Входные данные'!$C$57*1000), 2*SQRT('Входные данные'!$C$52*AE5*'Входные данные'!$C$54*SIN(RADIANS(H5))/AF5)/('Входные данные'!$C$57*1000)) -> 3.1457184 | V5: =2*U5 -> 6.2914367 | W5: =IFERROR(IF(T5>0,T5/V5,0),0) -> 14.90379 | X5: ='Входные данные'!$C$33+'Входные данные'!$C$34*((C5+D5)/2)/100 -> 24.5 | Y5: =IF(W5>1,"ОПАСНО: спирал. изгиб",IF(W5>0.5,"Внимание: синус. изгиб",IF(AO5<1,"ОПАСНО: гидроразрыв",IF(AR5<1.15,"ОПАСНО: смятие колонны",IF(AS5<1.1,"ОПАСНО: разрыв колонны",IF(AQ5<1.25,"ОПАСНО: текучесть стали",IF(ROW()=5,IF(S5>'Входные данные'!$C$44,"Превышение затяжки",IF(R5<'Входные данные'!$C$43,"Требуется разгрузка",IF(R5>'Входные данные'!$C$42,"Превышение грузоподъём.","Норма"))),"Норма"))))))) -> ОПАСНО: спирал. изгиб | Z5: =LOOKUP((C5+D5)/2, 'Входные данные'!$H$5:$H$7, 'Входные данные'!$J$5:$J$7) -> 244.5 | AA5: =LOOKUP((C5+D5)/2, 'Входные данные'!$H$5:$H$7, 'Входные данные'!$K$5:$K$7) -> 220.5 | AB5: =LOOKUP((C5+D5)/2, 'Входные данные'!$H$5:$H$7, 'Входные данные'!$M$5:$M$7) -> 758 | AC5: =LOOKUP((C5+D5)/2, 'Входные данные'!$H$5:$H$7, 'Входные данные'!$N$5:$N$7) -> 69.94 | AD5: =(Z5-AA5)/2 -> 12 | AE5: =PI()/64*((Z5/1000)^4-(AA5/1000)^4) -> 5.9383444e-05 | AF5: =(IF(I5="обс.", 'Входные данные'!$C$20, 'Входные данные'!$C$19)-Z5)/2000 -> 0.0367 | AG5: =1 / ( 1 / (2 * ('Входные данные'!$C$14 * 1000) / 0.91 / ((Z5/AD5) * (Z5/AD5 - 1)^2)) + 1 / (2 * AB5 * ((Z5/AD5) - 1) / (Z5/AD5)^2) ) -> 32.567369 | AH5: =0.875 * 2 * AB5 * AD5 / Z5 -> 65.104294 | AI5: ='Входные данные'!$C$30 * 'Входные данные'!$C$57 * 'Профиль ствола'!D6 / 1000000 -> 3.97305 | AJ5: ='Входные данные'!$C$47 * ( (Z5/1000)^2 / ( (IF(I5="обс.",'Входные данные'!$C$20,'Входные данные'!$C$19)/1000)^2 - (Z5/1000)^2 ) + 0.4 ) -> 0.92407968 | AK5: =12 * ('Входные данные'!$C$31/1000) * AJ5 / (AF5*2)^2 + 6 * 'Входные данные'!$C$32 / (AF5*2) -> 1277.6143 | AL5: =AK5*E5/1000000 -> 0.3832843 | AM5: =AI5+AL5 -> 4.3563343 | AN5: =AM5*1000000/('Входные данные'!$C$57*'Профиль ствола'!D6) -> 1480.2359 | AO5: ='Входные данные'!$C$58/AN5 -> 1.0809088 | AP5: =SQRT(((Q5+P5)*9810/(PI()*(Z5^2-AA5^2)/4))^2 + ('Входные данные'!$C$59*Z5/(2*AD5))^2 + (-( 'Входные данные'!$C$59 + 2*AI5 ) / 2)^2 - ((Q5+P5)*9810/(PI()*(Z5^2-AA5^2)/4))*('Входные данные'!$C$59*Z5/(2*AD5)) - ('Входные данные'!$C$59*Z5/(2*AD5))*(-( 'Входные данные'!$C$59 + 2*AI5 ) / 2) - (-( 'Входные данные'!$C$59 + 2*AI5 ) / 2)*((Q5+P5)*9810/(PI()*(Z5^2-AA5^2)/4))) -> 295.52108 | AQ5: =AB5/AP5 -> 2.5649608 | AR5: =AG5/AI5 -> 8.1970699 | AS5: =AH5/30 -> 2.1701431
B6: 2 | C6: ='Профиль ствола'!C6 -> 300 | D6: ='Профиль ствола'!C7 -> 600 | E6: =D6-C6 -> 300 | F6: ='Профиль ствола'!E6 -> 0 | G6: ='Профиль ствола'!E7 -> 0 | H6: =(F6+G6)/2 -> 0 | I6: =IF(C6<'Входные данные'!$C$21,"обс.","откр.") -> обс. | J6: =IF(I6="обс.",'Входные данные'!$C$38,'Входные данные'!$C$39) -> 0.25 | K6: =AC6*E6/1000 -> 20.982 | L6: =K6*'Входные данные'!$C$50 -> 17.373631 | M6: =L6*COS(RADIANS(H6)) -> 17.373631 | N6: =SQRT((L6*SIN(RADIANS(H6)))^2 + (Q6*ABS(G6-F6)*PI()/180)^2) -> 0 | O6: =N6*J6 -> 0 | P6: =O6+P7 -> 52.94976 | Q6: =M6+Q7 -> 139.18351 | R6: =Q6-P6+'Входные данные'!$C$43 -> 101.23375 | S6: =Q6+P6+'Входные данные'!$C$43 -> 207.13327 | T6: ='Входные данные'!$C$45 - Q7 + P7 -> 111.13988 | U6: =IF(H6<1, 1.94*(('Входные данные'!$C$52*AE6*('Входные данные'!$C$54^2))^(1/3))/('Входные данные'!$C$57*1000), 2*SQRT('Входные данные'!$C$52*AE6*'Входные данные'!$C$54*SIN(RADIANS(H6))/AF6)/('Входные данные'!$C$57*1000)) -> 3.1457184 | V6: =2*U6 -> 6.2914367 | W6: =IFERROR(IF(T6>0,T6/V6,0),0) -> 17.665263 | X6: ='Входные данные'!$C$33+'Входные данные'!$C$34*((C6+D6)/2)/100 -> 33.5 | Y6: =IF(W6>1,"ОПАСНО: спирал. изгиб",IF(W6>0.5,"Внимание: синус. изгиб",IF(AO6<1,"ОПАСНО: гидроразрыв",IF(AR6<1.15,"ОПАСНО: смятие колонны",IF(AS6<1.1,"ОПАСНО: разрыв колонны",IF(AQ6<1.25,"ОПАСНО: текучесть стали",IF(ROW()=5,IF(S6>'Входные данные'!$C$44,"Превышение затяжки",IF(R6<'Входные данные'!$C$43,"Требуется разгрузка",IF(R6>'Входные данные'!$C$42,"Превышение грузоподъём.","Норма"))),"Норма"))))))) -> ОПАСНО: спирал. изгиб | Z6: =LOOKUP((C6+D6)/2, 'Входные данные'!$H$5:$H$7, 'Входные данные'!$J$5:$J$7) -> 244.5 | AA6: =LOOKUP((C6+D6)/2, 'Входные данные'!$H$5:$H$7, 'Входные данные'!$K$5:$K$7) -> 220.5 | AB6: =LOOKUP((C6+D6)/2, 'Входные данные'!$H$5:$H$7, 'Входные данные'!$M$5:$M$7) -> 758 | AC6: =LOOKUP((C6+D6)/2, 'Входные данные'!$H$5:$H$7, 'Входные данные'!$N$5:$N$7) -> 69.94 | AD6: =(Z6-AA6)/2 -> 12 | AE6: =PI()/64*((Z6/1000)^4-(AA6/1000)^4) -> 5.9383444e-05 | AF6: =(IF(I6="обс.", 'Входные данные'!$C$20, 'Входные данные'!$C$19)-Z6)/2000 -> 0.0367 | AG6: =1 / ( 1 / (2 * ('Входные данные'!$C$14 * 1000) / 0.91 / ((Z6/AD6) * (Z6/AD6 - 1)^2)) + 1 / (2 * AB6 * ((Z6/AD6) - 1) / (Z6/AD6)^2) ) -> 32.567369 | AH6: =0.875 * 2 * AB6 * AD6 / Z6 -> 65.104294 | AI6: ='Входные данные'!$C$30 * 'Входные данные'!$C$57 * 'Профиль ствола'!D7 / 1000000 -> 7.9461 | AJ6: ='Входные данные'!$C$47 * ( (Z6/1000)^2 / ( (IF(I6="обс.",'Входные данные'!$C$20,'Входные данные'!$C$19)/1000)^2 - (Z6/1000)^2 ) + 0.4 ) -> 0.92407968 | AK6: =12 * ('Входные данные'!$C$31/1000) * AJ6 / (AF6*2)^2 + 6 * 'Входные данные'!$C$32 / (AF6*2) -> 1277.6143 | AL6: =AL5+AK6*E6/1000000 -> 0.7665686 | AM6: =AI6+AL6 -> 8.7126686 | AN6: =AM6*1000000/('Входные данные'!$C$57*'Профиль ствола'!D7) -> 1480.2359 | AO6: ='Входные данные'!$C$58/AN6 -> 1.0809088 | AP6: =SQRT(((Q6+P6)*9810/(PI()*(Z6^2-AA6^2)/4))^2 + ('Входные данные'!$C$59*Z6/(2*AD6))^2 + (-( 'Входные данные'!$C$59 + 2*AI6 ) / 2)^2 - ((Q6+P6)*9810/(PI()*(Z6^2-AA6^2)/4))*('Входные данные'!$C$59*Z6/(2*AD6)) - ('Входные данные'!$C$59*Z6/(2*AD6))*(-( 'Входные данные'!$C$59 + 2*AI6 ) / 2) - (-( 'Входные данные'!$C$59 + 2*AI6 ) / 2)*((Q6+P6)*9810/(PI()*(Z6^2-AA6^2)/4))) -> 293.94025 | AQ6: =AB6/AP6 -> 2.5787554 | AR6: =AG6/AI6 -> 4.098535 | AS6: =AH6/30 -> 2.1701431
B7: 3 | C7: ='Профиль ствола'!C7 -> 600 | D7: ='Профиль ствола'!C8 -> 750 | E7: =D7-C7 -> 150 | F7: ='Профиль ствола'!E7 -> 0 | G7: ='Профиль ствола'!E8 -> 15 | H7: =(F7+G7)/2 -> 7.5 | I7: =IF(C7<'Входные данные'!$C$21,"обс.","откр.") -> обс. | J7: =IF(I7="обс.",'Входные данные'!$C$38,'Входные данные'!$C$39) -> 0.25 | K7: =AC7*E7/1000 -> 10.491 | L7: =K7*'Входные данные'!$C$50 -> 8.6868153 | M7: =L7*COS(RADIANS(H7)) -> 8.6124984 | N7: =SQRT((L7*SIN(RADIANS(H7)))^2 + (Q7*ABS(G7-F7)*PI()/180)^2) -> 31.909903 | O7: =N7*J7 -> 7.9774757 | P7: =O7+P8 -> 52.94976 | Q7: =M7+Q8 -> 121.80988 | R7: =Q7-P7+'Входные данные'!$C$43 -> 83.860119 | S7: =Q7+P7+'Входные данные'!$C$43 -> 189.75964 | T7: ='Входные данные'!$C$45 - Q8 + P8 -> 111.7749 | U7: =IF(H7<1, 1.94*(('Входные данные'!$C$52*AE7*('Входные данные'!$C$54^2))^(1/3))/('Входные данные'!$C$57*1000), 2*SQRT('Входные данные'!$C$52*AE7*'Входные данные'!$C$54*SIN(RADIANS(H7))/AF7)/('Входные данные'!$C$57*1000)) -> 32.362219 | V7: =2*U7 -> 64.724438 | W7: =IFERROR(IF(T7>0,T7/V7,0),0) -> 1.7269351 | X7: ='Входные данные'!$C$33+'Входные данные'!$C$34*((C7+D7)/2)/100 -> 40.25 | Y7: =IF(W7>1,"ОПАСНО: спирал. изгиб",IF(W7>0.5,"Внимание: синус. изгиб",IF(AO7<1,"ОПАСНО: гидроразрыв",IF(AR7<1.15,"ОПАСНО: смятие колонны",IF(AS7<1.1,"ОПАСНО: разрыв колонны",IF(AQ7<1.25,"ОПАСНО: текучесть стали",IF(ROW()=5,IF(S7>'Входные данные'!$C$44,"Превышение затяжки",IF(R7<'Входные данные'!$C$43,"Требуется разгрузка",IF(R7>'Входные данные'!$C$42,"Превышение грузоподъём.","Норма"))),"Норма"))))))) -> ОПАСНО: спирал. изгиб | Z7: =LOOKUP((C7+D7)/2, 'Входные данные'!$H$5:$H$7, 'Входные данные'!$J$5:$J$7) -> 244.5 | AA7: =LOOKUP((C7+D7)/2, 'Входные данные'!$H$5:$H$7, 'Входные данные'!$K$5:$K$7) -> 220.5 | AB7: =LOOKUP((C7+D7)/2, 'Входные данные'!$H$5:$H$7, 'Входные данные'!$M$5:$M$7) -> 758 | AC7: =LOOKUP((C7+D7)/2, 'Входные данные'!$H$5:$H$7, 'Входные данные'!$N$5:$N$7) -> 69.94 | AD7: =(Z7-AA7)/2 -> 12 | AE7: =PI()/64*((Z7/1000)^4-(AA7/1000)^4) -> 5.9383444e-05 | AF7: =(IF(I7="обс.", 'Входные данные'!$C$20, 'Входные данные'!$C$19)-Z7)/2000 -> 0.0367 | AG7: =1 / ( 1 / (2 * ('Входные данные'!$C$14 * 1000) / 0.91 / ((Z7/AD7) * (Z7/AD7 - 1)^2)) + 1 / (2 * AB7 * ((Z7/AD7) - 1) / (Z7/AD7)^2) ) -> 32.567369 | AH7: =0.875 * 2 * AB7 * AD7 / Z7 -> 65.104294 | AI7: ='Входные данные'!$C$30 * 'Входные данные'!$C$57 * 'Профиль ствола'!D8 / 1000000 -> 9.906138 | AJ7: ='Входные данные'!$C$47 * ( (Z7/1000)^2 / ( (IF(I7="обс.",'Входные данные'!$C$20,'Входные данные'!$C$19)/1000)^2 - (Z7/1000)^2 ) + 0.4 ) -> 0.92407968 | AK7: =12 * ('Входные данные'!$C$31/1000) * AJ7 / (AF7*2)^2 + 6 * 'Входные данные'!$C$32 / (AF7*2) -> 1277.6143 | AL7: =AL6+AK7*E7/1000000 -> 0.95821075 | AM7: =AI7+AL7 -> 10.864349 | AN7: =AM7*1000000/('Входные данные'!$C$57*'Профиль ствола'!D8) -> 1480.5841 | AO7: ='Входные данные'!$C$58/AN7 -> 1.0806546 | AP7: =SQRT(((Q7+P7)*9810/(PI()*(Z7^2-AA7^2)/4))^2 + ('Входные данные'!$C$59*Z7/(2*AD7))^2 + (-( 'Входные данные'!$C$59 + 2*AI7 ) / 2)^2 - ((Q7+P7)*9810/(PI()*(Z7^2-AA7^2)/4))*('Входные данные'!$C$59*Z7/(2*AD7)) - ('Входные данные'!$C$59*Z7/(2*AD7))*(-( 'Входные данные'!$C$59 + 2*AI7 ) / 2) - (-( 'Входные данные'!$C$59 + 2*AI7 ) / 2)*((Q7+P7)*9810/(PI()*(Z7^2-AA7^2)/4))) -> 291.52875 | AQ7: =AB7/AP7 -> 2.6000867 | AR7: =AG7/AI7 -> 3.2875949 | AS7: =AH7/30 -> 2.1701431
B8: 4 | C8: ='Профиль ствола'!C8 -> 750 | D8: ='Профиль ствола'!C9 -> 900 | E8: =D8-C8 -> 150 | F8: ='Профиль ствола'!E8 -> 15 | G8: ='Профиль ствола'!E9 -> 30 | H8: =(F8+G8)/2 -> 22.5 | I8: =IF(C8<'Входные данные'!$C$21,"обс.","откр.") -> обс. | J8: =IF(I8="обс.",'Входные данные'!$C$38,'Входные данные'!$C$39) -> 0.25 | K8: =AC8*E8/1000 -> 10.491 | L8: =K8*'Входные данные'!$C$50 -> 8.6868153 | M8: =L8*COS(RADIANS(H8)) -> 8.0255708 | N8: =SQRT((L8*SIN(RADIANS(H8)))^2 + (Q8*ABS(G8-F8)*PI()/180)^2) -> 29.820873 | O8: =N8*J8 -> 7.4552184 | P8: =O8+P9 -> 44.972285 | Q8: =M8+Q9 -> 113.19738 | R8: =Q8-P8+'Входные данные'!$C$43 -> 83.225096 | S8: =Q8+P8+'Входные данные'!$C$43 -> 173.16967 | T8: ='Входные данные'!$C$45 - Q9 + P9 -> 112.34526 | U8: =IF(H8<1, 1.94*(('Входные данные'!$C$52*AE8*('Входные данные'!$C$54^2))^(1/3))/('Входные данные'!$C$57*1000), 2*SQRT('Входные данные'!$C$52*AE8*'Входные данные'!$C$54*SIN(RADIANS(H8))/AF8)/('Входные данные'!$C$57*1000)) -> 55.412697 | V8: =2*U8 -> 110.82539 | W8: =IFERROR(IF(T8>0,T8/V8,0),0) -> 1.013714 | X8: ='Входные данные'!$C$33+'Входные данные'!$C$34*((C8+D8)/2)/100 -> 44.75 | Y8: =IF(W8>1,"ОПАСНО: спирал. изгиб",IF(W8>0.5,"Внимание: синус. изгиб",IF(AO8<1,"ОПАСНО: гидроразрыв",IF(AR8<1.15,"ОПАСНО: смятие колонны",IF(AS8<1.1,"ОПАСНО: разрыв колонны",IF(AQ8<1.25,"ОПАСНО: текучесть стали",IF(ROW()=5,IF(S8>'Входные данные'!$C$44,"Превышение затяжки",IF(R8<'Входные данные'!$C$43,"Требуется разгрузка",IF(R8>'Входные данные'!$C$42,"Превышение грузоподъём.","Норма"))),"Норма"))))))) -> ОПАСНО: спирал. изгиб | Z8: =LOOKUP((C8+D8)/2, 'Входные данные'!$H$5:$H$7, 'Входные данные'!$J$5:$J$7) -> 244.5 | AA8: =LOOKUP((C8+D8)/2, 'Входные данные'!$H$5:$H$7, 'Входные данные'!$K$5:$K$7) -> 220.5 | AB8: =LOOKUP((C8+D8)/2, 'Входные данные'!$H$5:$H$7, 'Входные данные'!$M$5:$M$7) -> 758 | AC8: =LOOKUP((C8+D8)/2, 'Входные данные'!$H$5:$H$7, 'Входные данные'!$N$5:$N$7) -> 69.94 | AD8: =(Z8-AA8)/2 -> 12 | AE8: =PI()/64*((Z8/1000)^4-(AA8/1000)^4) -> 5.9383444e-05 | AF8: =(IF(I8="обс.", 'Входные данные'!$C$20, 'Входные данные'!$C$19)-Z8)/2000 -> 0.0367 | AG8: =1 / ( 1 / (2 * ('Входные данные'!$C$14 * 1000) / 0.91 / ((Z8/AD8) * (Z8/AD8 - 1)^2)) + 1 / (2 * AB8 * ((Z8/AD8) - 1) / (Z8/AD8)^2) ) -> 32.567369 | AH8: =0.875 * 2 * AB8 * AD8 / Z8 -> 65.104294 | AI8: ='Входные данные'!$C$30 * 'Входные данные'!$C$57 * 'Профиль ствола'!D9 / 1000000 -> 11.799959 | AJ8: ='Входные данные'!$C$47 * ( (Z8/1000)^2 / ( (IF(I8="обс.",'Входные данные'!$C$20,'Входные данные'!$C$19)/1000)^2 - (Z8/1000)^2 ) + 0.4 ) -> 0.92407968 | AK8: =12 * ('Входные данные'!$C$31/1000) * AJ8 / (AF8*2)^2 + 6 * 'Входные данные'!$C$32 / (AF8*2) -> 1277.6143 | AL8: =AL7+AK8*E8/1000000 -> 1.1498529 | AM8: =AI8+AL8 -> 12.949811 | AN8: =AM8*1000000/('Входные данные'!$C$57*'Профиль ствола'!D9) -> 1481.5514 | AO8: ='Входные данные'!$C$58/AN8 -> 1.079949 | AP8: =SQRT(((Q8+P8)*9810/(PI()*(Z8^2-AA8^2)/4))^2 + ('Входные данные'!$C$59*Z8/(2*AD8))^2 + (-( 'Входные данные'!$C$59 + 2*AI8 ) / 2)^2 - ((Q8+P8)*9810/(PI()*(Z8^2-AA8^2)/4))*('Входные данные'!$C$59*Z8/(2*AD8)) - ('Входные данные'!$C$59*Z8/(2*AD8))*(-( 'Входные данные'!$C$59 + 2*AI8 ) / 2) - (-( 'Входные данные'!$C$59 + 2*AI8 ) / 2)*((Q8+P8)*9810/(PI()*(Z8^2-AA8^2)/4))) -> 290.33527 | AQ8: =AB8/AP8 -> 2.6107747 | AR8: =AG8/AI8 -> 2.7599562 | AS8: =AH8/30 -> 2.1701431
B9: 5 | C9: ='Профиль ствола'!C9 -> 900 | D9: ='Профиль ствола'!C10 -> 1050 | E9: =D9-C9 -> 150 | F9: ='Профиль ствола'!E9 -> 30 | G9: ='Профиль ствола'!E10 -> 45 | H9: =(F9+G9)/2 -> 37.5 | I9: =IF(C9<'Входные данные'!$C$21,"обс.","откр.") -> обс. | J9: =IF(I9="обс.",'Входные данные'!$C$38,'Входные данные'!$C$39) -> 0.25 | K9: =AC9*E9/1000 -> 10.491 | L9: =K9*'Входные данные'!$C$50 -> 8.6868153 | M9: =L9*COS(RADIANS(H9)) -> 6.8917139 | N9: =SQRT((L9*SIN(RADIANS(H9)))^2 + (Q9*ABS(G9-F9)*PI()/180)^2) -> 28.037146 | O9: =N9*J9 -> 7.0092864 | P9: =O9+P10 -> 37.517066 | Q9: =M9+Q10 -> 105.17181 | R9: =Q9-P9+'Входные данные'!$C$43 -> 82.654744 | S9: =Q9+P9+'Входные данные'!$C$43 -> 157.68888 | T9: ='Входные данные'!$C$45 - Q10 + P10 -> 112.22768 | U9: =IF(H9<1, 1.94*(('Входные данные'!$C$52*AE9*('Входные данные'!$C$54^2))^(1/3))/('Входные данные'!$C$57*1000), 2*SQRT('Входные данные'!$C$52*AE9*'Входные данные'!$C$54*SIN(RADIANS(H9))/AF9)/('Входные данные'!$C$57*1000)) -> 69.889676 | V9: =2*U9 -> 139.77935 | W9: =IFERROR(IF(T9>0,T9/V9,0),0) -> 0.80289172 | X9: ='Входные данные'!$C$33+'Входные данные'!$C$34*((C9+D9)/2)/100 -> 49.25 | Y9: =IF(W9>1,"ОПАСНО: спирал. изгиб",IF(W9>0.5,"Внимание: синус. изгиб",IF(AO9<1,"ОПАСНО: гидроразрыв",IF(AR9<1.15,"ОПАСНО: смятие колонны",IF(AS9<1.1,"ОПАСНО: разрыв колонны",IF(AQ9<1.25,"ОПАСНО: текучесть стали",IF(ROW()=5,IF(S9>'Входные данные'!$C$44,"Превышение затяжки",IF(R9<'Входные данные'!$C$43,"Требуется разгрузка",IF(R9>'Входные данные'!$C$42,"Превышение грузоподъём.","Норма"))),"Норма"))))))) -> Внимание: синус. изгиб | Z9: =LOOKUP((C9+D9)/2, 'Входные данные'!$H$5:$H$7, 'Входные данные'!$J$5:$J$7) -> 244.5 | AA9: =LOOKUP((C9+D9)/2, 'Входные данные'!$H$5:$H$7, 'Входные данные'!$K$5:$K$7) -> 220.5 | AB9: =LOOKUP((C9+D9)/2, 'Входные данные'!$H$5:$H$7, 'Входные данные'!$M$5:$M$7) -> 758 | AC9: =LOOKUP((C9+D9)/2, 'Входные данные'!$H$5:$H$7, 'Входные данные'!$N$5:$N$7) -> 69.94 | AD9: =(Z9-AA9)/2 -> 12 | AE9: =PI()/64*((Z9/1000)^4-(AA9/1000)^4) -> 5.9383444e-05 | AF9: =(IF(I9="обс.", 'Входные данные'!$C$20, 'Входные данные'!$C$19)-Z9)/2000 -> 0.0367 | AG9: =1 / ( 1 / (2 * ('Входные данные'!$C$14 * 1000) / 0.91 / ((Z9/AD9) * (Z9/AD9 - 1)^2)) + 1 / (2 * AB9 * ((Z9/AD9) - 1) / (Z9/AD9)^2) ) -> 32.567369 | AH9: =0.875 * 2 * AB9 * AD9 / Z9 -> 65.104294 | AI9: ='Входные данные'!$C$30 * 'Входные данные'!$C$57 * 'Профиль ствола'!D10 / 1000000 -> 13.561344 | AJ9: ='Входные данные'!$C$47 * ( (Z9/1000)^2 / ( (IF(I9="обс.",'Входные данные'!$C$20,'Входные данные'!$C$19)/1000)^2 - (Z9/1000)^2 ) + 0.4 ) -> 0.92407968 | AK9: =12 * ('Входные данные'!$C$31/1000) * AJ9 / (AF9*2)^2 + 6 * 'Входные данные'!$C$32 / (AF9*2) -> 1277.6143 | AL9: =AL8+AK9*E9/1000000 -> 1.3414951 | AM9: =AI9+AL9 -> 14.902839 | AN9: =AM9*1000000/('Входные данные'!$C$57*'Профиль ствола'!D10) -> 1483.5427 | AO9: ='Входные данные'!$C$58/AN9 -> 1.0784995 | AP9: =SQRT(((Q9+P9)*9810/(PI()*(Z9^2-AA9^2)/4))^2 + ('Входные данные'!$C$59*Z9/(2*AD9))^2 + (-( 'Входные данные'!$C$59 + 2*AI9 ) / 2)^2 - ((Q9+P9)*9810/(PI()*(Z9^2-AA9^2)/4))*('Входные данные'!$C$59*Z9/(2*AD9)) - ('Входные данные'!$C$59*Z9/(2*AD9))*(-( 'Входные данные'!$C$59 + 2*AI9 ) / 2) - (-( 'Входные данные'!$C$59 + 2*AI9 ) / 2)*((Q9+P9)*9810/(PI()*(Z9^2-AA9^2)/4))) -> 290.18697 | AQ9: =AB9/AP9 -> 2.612109 | AR9: =AG9/AI9 -> 2.4014853 | AS9: =AH9/30 -> 2.1701431
B10: 6 | C10: ='Профиль ствола'!C10 -> 1050 | D10: ='Профиль ствола'!C11 -> 1500 | E10: =D10-C10 -> 450 | F10: ='Профиль ствола'!E10 -> 45 | G10: ='Профиль ствола'!E11 -> 45 | H10: =(F10+G10)/2 -> 45 | I10: =IF(C10<'Входные данные'!$C$21,"обс.","откр.") -> обс. | J10: =IF(I10="обс.",'Входные данные'!$C$38,'Входные данные'!$C$39) -> 0.25 | K10: =AC10*E10/1000 -> 31.473 | L10: =K10*'Входные данные'!$C$50 -> 26.060446 | M10: =L10*COS(RADIANS(H10)) -> 18.427518 | N10: =SQRT((L10*SIN(RADIANS(H10)))^2 + (Q10*ABS(G10-F10)*PI()/180)^2) -> 18.427518 | O10: =N10*J10 -> 4.6068795 | P10: =O10+P11 -> 30.50778 | Q10: =M10+Q11 -> 98.280096 | R10: =Q10-P10+'Входные данные'!$C$43 -> 82.772316 | S10: =Q10+P10+'Входные данные'!$C$43 -> 143.78788 | T10: ='Входные данные'!$C$45 - Q11 + P11 -> 126.04832 | U10: =IF(H10<1, 1.94*(('Входные данные'!$C$52*AE10*('Входные данные'!$C$54^2))^(1/3))/('Входные данные'!$C$57*1000), 2*SQRT('Входные данные'!$C$52*AE10*'Входные данные'!$C$54*SIN(RADIANS(H10))/AF10)/('Входные данные'!$C$57*1000)) -> 75.323755 | V10: =2*U10 -> 150.64751 | W10: =IFERROR(IF(T10>0,T10/V10,0),0) -> 0.83671029 | X10: ='Входные данные'!$C$33+'Входные данные'!$C$34*((C10+D10)/2)/100 -> 58.25 | Y10: =IF(W10>1,"ОПАСНО: спирал. изгиб",IF(W10>0.5,"Внимание: синус. изгиб",IF(AO10<1,"ОПАСНО: гидроразрыв",IF(AR10<1.15,"ОПАСНО: смятие колонны",IF(AS10<1.1,"ОПАСНО: разрыв колонны",IF(AQ10<1.25,"ОПАСНО: текучесть стали",IF(ROW()=5,IF(S10>'Входные данные'!$C$44,"Превышение затяжки",IF(R10<'Входные данные'!$C$43,"Требуется разгрузка",IF(R10>'Входные данные'!$C$42,"Превышение грузоподъём.","Норма"))),"Норма"))))))) -> Внимание: синус. изгиб | Z10: =LOOKUP((C10+D10)/2, 'Входные данные'!$H$5:$H$7, 'Входные данные'!$J$5:$J$7) -> 244.5 | AA10: =LOOKUP((C10+D10)/2, 'Входные данные'!$H$5:$H$7, 'Входные данные'!$K$5:$K$7) -> 220.5 | AB10: =LOOKUP((C10+D10)/2, 'Входные данные'!$H$5:$H$7, 'Входные данные'!$M$5:$M$7) -> 758 | AC10: =LOOKUP((C10+D10)/2, 'Входные данные'!$H$5:$H$7, 'Входные данные'!$N$5:$N$7) -> 69.94 | AD10: =(Z10-AA10)/2 -> 12 | AE10: =PI()/64*((Z10/1000)^4-(AA10/1000)^4) -> 5.9383444e-05 | AF10: =(IF(I10="обс.", 'Входные данные'!$C$20, 'Входные данные'!$C$19)-Z10)/2000 -> 0.0367 | AG10: =1 / ( 1 / (2 * ('Входные данные'!$C$14 * 1000) / 0.91 / ((Z10/AD10) * (Z10/AD10 - 1)^2)) + 1 / (2 * AB10 * ((Z10/AD10) - 1) / (Z10/AD10)^2) ) -> 32.567369 | AH10: =0.875 * 2 * AB10 * AD10 / Z10 -> 65.104294 | AI10: ='Входные данные'!$C$30 * 'Входные данные'!$C$57 * 'Профиль ствола'!D11 / 1000000 -> 17.759533 | AJ10: ='Входные данные'!$C$47 * ( (Z10/1000)^2 / ( (IF(I10="обс.",'Входные данные'!$C$20,'Входные данные'!$C$19)/1000)^2 - (Z10/1000)^2 ) + 0.4 ) -> 0.92407968 | AK10: =12 * ('Входные данные'!$C$31/1000) * AJ10 / (AF10*2)^2 + 6 * 'Входные данные'!$C$32 / (AF10*2) -> 1277.6143 | AL10: =AL9+AK10*E10/1000000 -> 1.9164215 | AM10: =AI10+AL10 -> 19.675955 | AN10: =AM10*1000000/('Входные данные'!$C$57*'Профиль ствола'!D11) -> 1495.6778 | AO10: ='Входные данные'!$C$58/AN10 -> 1.0697491 | AP10: =SQRT(((Q10+P10)*9810/(PI()*(Z10^2-AA10^2)/4))^2 + ('Входные данные'!$C$59*Z10/(2*AD10))^2 + (-( 'Входные данные'!$C$59 + 2*AI10 ) / 2)^2 - ((Q10+P10)*9810/(PI()*(Z10^2-AA10^2)/4))*('Входные данные'!$C$59*Z10/(2*AD10)) - ('Входные данные'!$C$59*Z10/(2*AD10))*(-( 'Входные данные'!$C$59 + 2*AI10 ) / 2) - (-( 'Входные данные'!$C$59 + 2*AI10 ) / 2)*((Q10+P10)*9810/(PI()*(Z10^2-AA10^2)/4))) -> 293.15098 | AQ10: =AB10/AP10 -> 2.5856983 | AR10: =AG10/AI10 -> 1.8337964 | AS10: =AH10/30 -> 2.1701431
B11: 7 | C11: ='Профиль ствола'!C11 -> 1500 | D11: ='Профиль ствола'!C12 -> 2000 | E11: =D11-C11 -> 500 | F11: ='Профиль ствола'!E11 -> 45 | G11: ='Профиль ствола'!E12 -> 45 | H11: =(F11+G11)/2 -> 45 | I11: =IF(C11<'Входные данные'!$C$21,"обс.","откр.") -> обс. | J11: =IF(I11="обс.",'Входные данные'!$C$38,'Входные данные'!$C$39) -> 0.25 | K11: =AC11*E11/1000 -> 34.97 | L11: =K11*'Входные данные'!$C$50 -> 28.956051 | M11: =L11*COS(RADIANS(H11)) -> 20.47502 | N11: =SQRT((L11*SIN(RADIANS(H11)))^2 + (Q11*ABS(G11-F11)*PI()/180)^2) -> 20.47502 | O11: =N11*J11 -> 5.118755 | P11: =O11+P12 -> 25.9009 | Q11: =M11+Q12 -> 79.852578 | R11: =Q11-P11+'Входные данные'!$C$43 -> 68.951678 | S11: =Q11+P11+'Входные данные'!$C$43 -> 120.75348 | T11: ='Входные данные'!$C$45 - Q12 + P12 -> 141.40459 | U11: =IF(H11<1, 1.94*(('Входные данные'!$C$52*AE11*('Входные данные'!$C$54^2))^(1/3))/('Входные данные'!$C$57*1000), 2*SQRT('Входные данные'!$C$52*AE11*'Входные данные'!$C$54*SIN(RADIANS(H11))/AF11)/('Входные данные'!$C$57*1000)) -> 75.323755 | V11: =2*U11 -> 150.64751 | W11: =IFERROR(IF(T11>0,T11/V11,0),0) -> 0.93864537 | X11: ='Входные данные'!$C$33+'Входные данные'!$C$34*((C11+D11)/2)/100 -> 72.5 | Y11: =IF(W11>1,"ОПАСНО: спирал. изгиб",IF(W11>0.5,"Внимание: синус. изгиб",IF(AO11<1,"ОПАСНО: гидроразрыв",IF(AR11<1.15,"ОПАСНО: смятие колонны",IF(AS11<1.1,"ОПАСНО: разрыв колонны",IF(AQ11<1.25,"ОПАСНО: текучесть стали",IF(ROW()=5,IF(S11>'Входные данные'!$C$44,"Превышение затяжки",IF(R11<'Входные данные'!$C$43,"Требуется разгрузка",IF(R11>'Входные данные'!$C$42,"Превышение грузоподъём.","Норма"))),"Норма"))))))) -> Внимание: синус. изгиб | Z11: =LOOKUP((C11+D11)/2, 'Входные данные'!$H$5:$H$7, 'Входные данные'!$J$5:$J$7) -> 244.5 | AA11: =LOOKUP((C11+D11)/2, 'Входные данные'!$H$5:$H$7, 'Входные данные'!$K$5:$K$7) -> 220.5 | AB11: =LOOKUP((C11+D11)/2, 'Входные данные'!$H$5:$H$7, 'Входные данные'!$M$5:$M$7) -> 758 | AC11: =LOOKUP((C11+D11)/2, 'Входные данные'!$H$5:$H$7, 'Входные данные'!$N$5:$N$7) -> 69.94 | AD11: =(Z11-AA11)/2 -> 12 | AE11: =PI()/64*((Z11/1000)^4-(AA11/1000)^4) -> 5.9383444e-05 | AF11: =(IF(I11="обс.", 'Входные данные'!$C$20, 'Входные данные'!$C$19)-Z11)/2000 -> 0.0367 | AG11: =1 / ( 1 / (2 * ('Входные данные'!$C$14 * 1000) / 0.91 / ((Z11/AD11) * (Z11/AD11 - 1)^2)) + 1 / (2 * AB11 * ((Z11/AD11) - 1) / (Z11/AD11)^2) ) -> 32.567369 | AH11: =0.875 * 2 * AB11 * AD11 / Z11 -> 65.104294 | AI11: ='Входные данные'!$C$30 * 'Входные данные'!$C$57 * 'Профиль ствола'!D12 / 1000000 -> 22.434489 | AJ11: ='Входные данные'!$C$47 * ( (Z11/1000)^2 / ( (IF(I11="обс.",'Входные данные'!$C$20,'Входные данные'!$C$19)/1000)^2 - (Z11/1000)^2 ) + 0.4 ) -> 0.92407968 | AK11: =12 * ('Входные данные'!$C$31/1000) * AJ11 / (AF11*2)^2 + 6 * 'Входные данные'!$C$32 / (AF11*2) -> 1277.6143 | AL11: =AL10+AK11*E11/1000000 -> 2.5552287 | AM11: =AI11+AL11 -> 24.989718 | AN11: =AM11*1000000/('Входные данные'!$C$57*'Профиль ствола'!D12) -> 1503.7614 | AO11: ='Входные данные'!$C$58/AN11 -> 1.0639986 | AP11: =SQRT(((Q11+P11)*9810/(PI()*(Z11^2-AA11^2)/4))^2 + ('Входные данные'!$C$59*Z11/(2*AD11))^2 + (-( 'Входные данные'!$C$59 + 2*AI11 ) / 2)^2 - ((Q11+P11)*9810/(PI()*(Z11^2-AA11^2)/4))*('Входные данные'!$C$59*Z11/(2*AD11)) - ('Входные данные'!$C$59*Z11/(2*AD11))*(-( 'Входные данные'!$C$59 + 2*AI11 ) / 2) - (-( 'Входные данные'!$C$59 + 2*AI11 ) / 2)*((Q11+P11)*9810/(PI()*(Z11^2-AA11^2)/4))) -> 297.51457 | AQ11: =AB11/AP11 -> 2.5477744 | AR11: =AG11/AI11 -> 1.4516653 | AS11: =AH11/30 -> 2.1701431
B12: 8 | C12: ='Профиль ствола'!C12 -> 2000 | D12: ='Профиль ствола'!C13 -> 2500 | E12: =D12-C12 -> 500 | F12: ='Профиль ствола'!E12 -> 45 | G12: ='Профиль ствола'!E13 -> 45 | H12: =(F12+G12)/2 -> 45 | I12: =IF(C12<'Входные данные'!$C$21,"обс.","откр.") -> откр. | J12: =IF(I12="обс.",'Входные данные'!$C$38,'Входные данные'!$C$39) -> 0.35 | K12: =AC12*E12/1000 -> 34.97 | L12: =K12*'Входные данные'!$C$50 -> 28.956051 | M12: =L12*COS(RADIANS(H12)) -> 20.47502 | N12: =SQRT((L12*SIN(RADIANS(H12)))^2 + (Q12*ABS(G12-F12)*PI()/180)^2) -> 20.47502 | O12: =N12*J12 -> 7.166257 | P12: =O12+P13 -> 20.782145 | Q12: =M12+Q13 -> 59.377558 | R12: =Q12-P12+'Входные данные'!$C$43 -> 53.595413 | S12: =Q12+P12+'Входные данные'!$C$43 -> 95.159703 | T12: ='Входные данные'!$C$45 - Q13 + P13 -> 154.71335 | U12: =IF(H12<1, 1.94*(('Входные данные'!$C$52*AE12*('Входные данные'!$C$54^2))^(1/3))/('Входные данные'!$C$57*1000), 2*SQRT('Входные данные'!$C$52*AE12*'Входные данные'!$C$54*SIN(RADIANS(H12))/AF12)/('Входные данные'!$C$57*1000)) -> 79.01637 | V12: =2*U12 -> 158.03274 | W12: =IFERROR(IF(T12>0,T12/V12,0),0) -> 0.97899556 | X12: ='Входные данные'!$C$33+'Входные данные'!$C$34*((C12+D12)/2)/100 -> 87.5 | Y12: =IF(W12>1,"ОПАСНО: спирал. изгиб",IF(W12>0.5,"Внимание: синус. изгиб",IF(AO12<1,"ОПАСНО: гидроразрыв",IF(AR12<1.15,"ОПАСНО: смятие колонны",IF(AS12<1.1,"ОПАСНО: разрыв колонны",IF(AQ12<1.25,"ОПАСНО: текучесть стали",IF(ROW()=5,IF(S12>'Входные данные'!$C$44,"Превышение затяжки",IF(R12<'Входные данные'!$C$43,"Требуется разгрузка",IF(R12>'Входные данные'!$C$42,"Превышение грузоподъём.","Норма"))),"Норма"))))))) -> Внимание: синус. изгиб | Z12: =LOOKUP((C12+D12)/2, 'Входные данные'!$H$5:$H$7, 'Входные данные'!$J$5:$J$7) -> 244.5 | AA12: =LOOKUP((C12+D12)/2, 'Входные данные'!$H$5:$H$7, 'Входные данные'!$K$5:$K$7) -> 220.5 | AB12: =LOOKUP((C12+D12)/2, 'Входные данные'!$H$5:$H$7, 'Входные данные'!$M$5:$M$7) -> 758 | AC12: =LOOKUP((C12+D12)/2, 'Входные данные'!$H$5:$H$7, 'Входные данные'!$N$5:$N$7) -> 69.94 | AD12: =(Z12-AA12)/2 -> 12 | AE12: =PI()/64*((Z12/1000)^4-(AA12/1000)^4) -> 5.9383444e-05 | AF12: =(IF(I12="обс.", 'Входные данные'!$C$20, 'Входные данные'!$C$19)-Z12)/2000 -> 0.03335 | AG12: =1 / ( 1 / (2 * ('Входные данные'!$C$14 * 1000) / 0.91 / ((Z12/AD12) * (Z12/AD12 - 1)^2)) + 1 / (2 * AB12 * ((Z12/AD12) - 1) / (Z12/AD12)^2) ) -> 32.567369 | AH12: =0.875 * 2 * AB12 * AD12 / Z12 -> 65.104294 | AI12: ='Входные данные'!$C$30 * 'Входные данные'!$C$57 * 'Профиль ствола'!D13 / 1000000 -> 27.122688 | AJ12: ='Входные данные'!$C$47 * ( (Z12/1000)^2 / ( (IF(I12="обс.",'Входные данные'!$C$20,'Входные данные'!$C$19)/1000)^2 - (Z12/1000)^2 ) + 0.4 ) -> 1.0064204 | AK12: =12 * ('Входные данные'!$C$31/1000) * AJ12 / (AF12*2)^2 + 6 * 'Входные данные'!$C$32 / (AF12*2) -> 1417.1908 | AL12: =AL11+AK12*E12/1000000 -> 3.2638241 | AM12: =AI12+AL12 -> 30.386512 | AN12: =AM12*1000000/('Входные данные'!$C$57*'Профиль ствола'!D13) -> 1512.453 | AO12: ='Входные данные'!$C$58/AN12 -> 1.0578841 | AP12: =SQRT(((Q12+P12)*9810/(PI()*(Z12^2-AA12^2)/4))^2 + ('Входные данные'!$C$59*Z12/(2*AD12))^2 + (-( 'Входные данные'!$C$59 + 2*AI12 ) / 2)^2 - ((Q12+P12)*9810/(PI()*(Z12^2-AA12^2)/4))*('Входные данные'!$C$59*Z12/(2*AD12)) - ('Входные данные'!$C$59*Z12/(2*AD12))*(-( 'Входные данные'!$C$59 + 2*AI12 ) / 2) - (-( 'Входные данные'!$C$59 + 2*AI12 ) / 2)*((Q12+P12)*9810/(PI()*(Z12^2-AA12^2)/4))) -> 304.07775 | AQ12: =AB12/AP12 -> 2.4927835 | AR12: =AG12/AI12 -> 1.2007427 | AS12: =AH12/30 -> 2.1701431
B13: 9 | C13: ='Профиль ствола'!C13 -> 2500 | D13: ='Профиль ствола'!C14 -> 3000 | E13: =D13-C13 -> 500 | F13: ='Профиль ствола'!E13 -> 45 | G13: ='Профиль ствола'!E14 -> 45 | H13: =(F13+G13)/2 -> 45 | I13: =IF(C13<'Входные данные'!$C$21,"обс.","откр.") -> откр. | J13: =IF(I13="обс.",'Входные данные'!$C$38,'Входные данные'!$C$39) -> 0.35 | K13: =AC13*E13/1000 -> 34.97 | L13: =K13*'Входные данные'!$C$50 -> 28.956051 | M13: =L13*COS(RADIANS(H13)) -> 20.47502 | N13: =SQRT((L13*SIN(RADIANS(H13)))^2 + (Q13*ABS(G13-F13)*PI()/180)^2) -> 20.47502 | O13: =N13*J13 -> 7.166257 | P13: =O13+P14 -> 13.615888 | Q13: =M13+Q14 -> 38.902538 | R13: =Q13-P13+'Входные данные'!$C$43 -> 40.28665 | S13: =Q13+P13+'Входные данные'!$C$43 -> 67.518426 | T13: ='Входные данные'!$C$45 - Q14 + P14 -> 168.02211 | U13: =IF(H13<1, 1.94*(('Входные данные'!$C$52*AE13*('Входные данные'!$C$54^2))^(1/3))/('Входные данные'!$C$57*1000), 2*SQRT('Входные данные'!$C$52*AE13*'Входные данные'!$C$54*SIN(RADIANS(H13))/AF13)/('Входные данные'!$C$57*1000)) -> 79.01637 | V13: =2*U13 -> 158.03274 | W13: =IFERROR(IF(T13>0,T13/V13,0),0) -> 1.0632108 | X13: ='Входные данные'!$C$33+'Входные данные'!$C$34*((C13+D13)/2)/100 -> 102.5 | Y13: =IF(W13>1,"ОПАСНО: спирал. изгиб",IF(W13>0.5,"Внимание: синус. изгиб",IF(AO13<1,"ОПАСНО: гидроразрыв",IF(AR13<1.15,"ОПАСНО: смятие колонны",IF(AS13<1.1,"ОПАСНО: разрыв колонны",IF(AQ13<1.25,"ОПАСНО: текучесть стали",IF(ROW()=5,IF(S13>'Входные данные'!$C$44,"Превышение затяжки",IF(R13<'Входные данные'!$C$43,"Требуется разгрузка",IF(R13>'Входные данные'!$C$42,"Превышение грузоподъём.","Норма"))),"Норма"))))))) -> ОПАСНО: спирал. изгиб | Z13: =LOOKUP((C13+D13)/2, 'Входные данные'!$H$5:$H$7, 'Входные данные'!$J$5:$J$7) -> 244.5 | AA13: =LOOKUP((C13+D13)/2, 'Входные данные'!$H$5:$H$7, 'Входные данные'!$K$5:$K$7) -> 220.5 | AB13: =LOOKUP((C13+D13)/2, 'Входные данные'!$H$5:$H$7, 'Входные данные'!$M$5:$M$7) -> 758 | AC13: =LOOKUP((C13+D13)/2, 'Входные данные'!$H$5:$H$7, 'Входные данные'!$N$5:$N$7) -> 69.94 | AD13: =(Z13-AA13)/2 -> 12 | AE13: =PI()/64*((Z13/1000)^4-(AA13/1000)^4) -> 5.9383444e-05 | AF13: =(IF(I13="обс.", 'Входные данные'!$C$20, 'Входные данные'!$C$19)-Z13)/2000 -> 0.03335 | AG13: =1 / ( 1 / (2 * ('Входные данные'!$C$14 * 1000) / 0.91 / ((Z13/AD13) * (Z13/AD13 - 1)^2)) + 1 / (2 * AB13 * ((Z13/AD13) - 1) / (Z13/AD13)^2) ) -> 32.567369 | AH13: =0.875 * 2 * AB13 * AD13 / Z13 -> 65.104294 | AI13: ='Входные данные'!$C$30 * 'Входные данные'!$C$57 * 'Профиль ствола'!D14 / 1000000 -> 31.797643 | AJ13: ='Входные данные'!$C$47 * ( (Z13/1000)^2 / ( (IF(I13="обс.",'Входные данные'!$C$20,'Входные данные'!$C$19)/1000)^2 - (Z13/1000)^2 ) + 0.4 ) -> 1.0064204 | AK13: =12 * ('Входные данные'!$C$31/1000) * AJ13 / (AF13*2)^2 + 6 * 'Входные данные'!$C$32 / (AF13*2) -> 1417.1908 | AL13: =AL12+AK13*E13/1000000 -> 3.9724195 | AM13: =AI13+AL13 -> 35.770063 | AN13: =AM13*1000000/('Входные данные'!$C$57*'Профиль ствола'!D14) -> 1518.6529 | AO13: ='Входные данные'!$C$58/AN13 -> 1.0535653 | AP13: =SQRT(((Q13+P13)*9810/(PI()*(Z13^2-AA13^2)/4))^2 + ('Входные данные'!$C$59*Z13/(2*AD13))^2 + (-( 'Входные данные'!$C$59 + 2*AI13 ) / 2)^2 - ((Q13+P13)*9810/(PI()*(Z13^2-AA13^2)/4))*('Входные данные'!$C$59*Z13/(2*AD13)) - ('Входные данные'!$C$59*Z13/(2*AD13))*(-( 'Входные данные'!$C$59 + 2*AI13 ) / 2) - (-( 'Входные данные'!$C$59 + 2*AI13 ) / 2)*((Q13+P13)*9810/(PI()*(Z13^2-AA13^2)/4))) -> 313.27378 | AQ13: =AB13/AP13 -> 2.4196088 | AR13: =AG13/AI13 -> 1.024207 | AS13: =AH13/30 -> 2.1701431
B14: 10 | C14: ='Профиль ствола'!C14 -> 3000 | D14: ='Профиль ствола'!C15 -> 3450 | E14: =D14-C14 -> 450 | F14: ='Профиль ствола'!E14 -> 45 | G14: ='Профиль ствола'!E15 -> 45 | H14: =(F14+G14)/2 -> 45 | I14: =IF(C14<'Входные данные'!$C$21,"обс.","откр.") -> откр. | J14: =IF(I14="обс.",'Входные данные'!$C$38,'Входные данные'!$C$39) -> 0.35 | K14: =AC14*E14/1000 -> 31.473 | L14: =K14*'Входные данные'!$C$50 -> 26.060446 | M14: =L14*COS(RADIANS(H14)) -> 18.427518 | N14: =SQRT((L14*SIN(RADIANS(H14)))^2 + (Q14*ABS(G14-F14)*PI()/180)^2) -> 18.427518 | O14: =N14*J14 -> 6.4496313 | P14: =O14 -> 6.4496313 | Q14: =M14 -> 18.427518 | R14: =Q14-P14+'Входные данные'!$C$43 -> 26.977887 | S14: =Q14+P14+'Входные данные'!$C$43 -> 39.877149 | T14: ='Входные данные'!$C$45 - Q15 + P15 -> 180 | U14: =IF(H14<1, 1.94*(('Входные данные'!$C$52*AE14*('Входные данные'!$C$54^2))^(1/3))/('Входные данные'!$C$57*1000), 2*SQRT('Входные данные'!$C$52*AE14*'Входные данные'!$C$54*SIN(RADIANS(H14))/AF14)/('Входные данные'!$C$57*1000)) -> 79.01637 | V14: =2*U14 -> 158.03274 | W14: =IFERROR(IF(T14>0,T14/V14,0),0) -> 1.1390045 | X14: ='Входные данные'!$C$33+'Входные данные'!$C$34*((C14+D14)/2)/100 -> 116.75 | Y14: =IF(W14>1,"ОПАСНО: спирал. изгиб",IF(W14>0.5,"Внимание: синус. изгиб",IF(AO14<1,"ОПАСНО: гидроразрыв",IF(AR14<1.15,"ОПАСНО: смятие колонны",IF(AS14<1.1,"ОПАСНО: разрыв колонны",IF(AQ14<1.25,"ОПАСНО: текучесть стали",IF(ROW()=5,IF(S14>'Входные данные'!$C$44,"Превышение затяжки",IF(R14<'Входные данные'!$C$43,"Требуется разгрузка",IF(R14>'Входные данные'!$C$42,"Превышение грузоподъём.","Норма"))),"Норма"))))))) -> ОПАСНО: спирал. изгиб | Z14: =LOOKUP((C14+D14)/2, 'Входные данные'!$H$5:$H$7, 'Входные данные'!$J$5:$J$7) -> 244.5 | AA14: =LOOKUP((C14+D14)/2, 'Входные данные'!$H$5:$H$7, 'Входные данные'!$K$5:$K$7) -> 220.5 | AB14: =LOOKUP((C14+D14)/2, 'Входные данные'!$H$5:$H$7, 'Входные данные'!$M$5:$M$7) -> 758 | AC14: =LOOKUP((C14+D14)/2, 'Входные данные'!$H$5:$H$7, 'Входные данные'!$N$5:$N$7) -> 69.94 | AD14: =(Z14-AA14)/2 -> 12 | AE14: =PI()/64*((Z14/1000)^4-(AA14/1000)^4) -> 5.9383444e-05 | AF14: =(IF(I14="обс.", 'Входные данные'!$C$20, 'Входные данные'!$C$19)-Z14)/2000 -> 0.03335 | AG14: =1 / ( 1 / (2 * ('Входные данные'!$C$14 * 1000) / 0.91 / ((Z14/AD14) * (Z14/AD14 - 1)^2)) + 1 / (2 * AB14 * ((Z14/AD14) - 1) / (Z14/AD14)^2) ) -> 32.567369 | AH14: =0.875 * 2 * AB14 * AD14 / Z14 -> 65.104294 | AI14: ='Входные данные'!$C$30 * 'Входные данные'!$C$57 * 'Профиль ствола'!D15 / 1000000 -> 35.691232 | AJ14: ='Входные данные'!$C$47 * ( (Z14/1000)^2 / ( (IF(I14="обс.",'Входные данные'!$C$20,'Входные данные'!$C$19)/1000)^2 - (Z14/1000)^2 ) + 0.4 ) -> 1.0064204 | AK14: =12 * ('Входные данные'!$C$31/1000) * AJ14 / (AF14*2)^2 + 6 * 'Входные данные'!$C$32 / (AF14*2) -> 1417.1908 | AL14: =AL13+AK14*E14/1000000 -> 4.6101554 | AM14: =AI14+AL14 -> 40.301388 | AN14: =AM14*1000000/('Входные данные'!$C$57*'Профиль ствола'!D15) -> 1524.3764 | AO14: ='Входные данные'!$C$58/AN14 -> 1.0496095 | AP14: =SQRT(((Q14+P14)*9810/(PI()*(Z14^2-AA14^2)/4))^2 + ('Входные данные'!$C$59*Z14/(2*AD14))^2 + (-( 'Входные данные'!$C$59 + 2*AI14 ) / 2)^2 - ((Q14+P14)*9810/(PI()*(Z14^2-AA14^2)/4))*('Входные данные'!$C$59*Z14/(2*AD14)) - ('Входные данные'!$C$59*Z14/(2*AD14))*(-( 'Входные данные'!$C$59 + 2*AI14 ) / 2) - (-( 'Входные данные'!$C$59 + 2*AI14 ) / 2)*((Q14+P14)*9810/(PI()*(Z14^2-AA14^2)/4))) -> 324.26204 | AQ14: =AB14/AP14 -> 2.3376156 | AR14: =AG14/AI14 -> 0.91247532 | AS14: =AH14/30 -> 2.1701431

Sheet Графики
B2: ГРАФИКИ И ВИЗУАЛИЗАЦИЯ
B3: Все графики построены на данных листа «Расчёт». Обновляются автоматически при изменении входных данных.
B4: MD, м | C4: Грузоподъём., т | D4: Макс. затяжка, т | E4: Макс. разгрузка, т | F4: Вес талевой, т
B5: =Расчёт!C5 -> 0 | C5: ='Входные данные'!$C$42 -> 250 | D5: ='Входные данные'!$C$44 -> 200 | E5: ='Входные данные'!$C$45 -> 180 | F5: ='Входные данные'!$C$43 -> 15
B6: =Расчёт!C6 -> 300 | C6: ='Входные данные'!$C$42 -> 250 | D6: ='Входные данные'!$C$44 -> 200 | E6: ='Входные данные'!$C$45 -> 180 | F6: ='Входные данные'!$C$43 -> 15
B7: =Расчёт!C7 -> 600 | C7: ='Входные данные'!$C$42 -> 250 | D7: ='Входные данные'!$C$44 -> 200 | E7: ='Входные данные'!$C$45 -> 180 | F7: ='Входные данные'!$C$43 -> 15
B8: =Расчёт!C8 -> 750 | C8: ='Входные данные'!$C$42 -> 250 | D8: ='Входные данные'!$C$44 -> 200 | E8: ='Входные данные'!$C$45 -> 180 | F8: ='Входные данные'!$C$43 -> 15
B9: =Расчёт!C9 -> 900 | C9: ='Входные данные'!$C$42 -> 250 | D9: ='Входные данные'!$C$44 -> 200 | E9: ='Входные данные'!$C$45 -> 180 | F9: ='Входные данные'!$C$43 -> 15
B10: =Расчёт!C10 -> 1050 | C10: ='Входные данные'!$C$42 -> 250 | D10: ='Входные данные'!$C$44 -> 200 | E10: ='Входные данные'!$C$45 -> 180 | F10: ='Входные данные'!$C$43 -> 15
B11: =Расчёт!C11 -> 1500 | C11: ='Входные данные'!$C$42 -> 250 | D11: ='Входные данные'!$C$44 -> 200 | E11: ='Входные данные'!$C$45 -> 180 | F11: ='Входные данные'!$C$43 -> 15
B12: =Расчёт!C12 -> 2000 | C12: ='Входные данные'!$C$42 -> 250 | D12: ='Входные данные'!$C$44 -> 200 | E12: ='Входные данные'!$C$45 -> 180 | F12: ='Входные данные'!$C$43 -> 15
B13: =Расчёт!C13 -> 2500 | C13: ='Входные данные'!$C$42 -> 250 | D13: ='Входные данные'!$C$44 -> 200 | E13: ='Входные данные'!$C$45 -> 180 | F13: ='Входные данные'!$C$43 -> 15
B14: =Расчёт!C14 -> 3000 | C14: ='Входные данные'!$C$42 -> 250 | D14: ='Входные данные'!$C$44 -> 200 | E14: ='Входные данные'!$C$45 -> 180 | F14: ='Входные данные'!$C$43 -> 15

Sheet Сводка
B2: СВОДКА И РЕКОМЕНДАЦИИ ПО СПУСКУ КОЛОННЫ
B4: 1. Ключевые показатели эффективности и прочности (KPI)
B5: Показатель | C5: Значение | D5: Ед. изм. | E5: Запас / Ограничение | F5: Статус безопасности
B6: Максимальная нагрузка при подъеме (Overpull) | C6: =MAX(Расчёт!S5:S14) -> 224.5069 | D6: т | E6: ="Предел: " & 'Входные данные'!$C$44 & " т" -> Предел: 200 т | F6: =IF(C6>'Входные данные'!$C$44, "КРИТИЧЕСКИЙ РИСК", IF(C6>'Входные данные'!$C$42/'Входные данные'!$C$46, "Внимание: близко к лимиту", "В норме")) -> КРИТИЧЕСКИЙ РИСК
B7: Минимальная нагрузка при спуске (Slack-off) | C7: =MIN(Расчёт!R5:R14) -> 26.977887 | D7: т | E7: ="Вес блока: " & 'Входные данные'!$C$43 & " т" -> Вес блока: 15 т | F7: =IF(C7<'Входные данные'!$C$43, "Разгрузка ниже веса блока", "В норме") -> В норме
B8: Максимальный коэффициент изгиба (Buckling) | C8: =MAX(Расчёт!W5:W14) -> 17.665263 | D8: — | E8: Предел: 1.00 | F8: =IF(C8>1, "КРИТИЧЕСКИЙ РИСК: спирал. изгиб", IF(C8>0.5, "Внимание: синус. изгиб", "В норме")) -> КРИТИЧЕСКИЙ РИСК: спирал. изгиб
B9: Максимальная эквивалентная плотность (ECD) | C9: =MAX(Расчёт!AN5:AN14) -> 1524.3764 | D9: кг/м³ | E9: ="Предел поглощения: " & 'Входные данные'!$C$58 & " кг/м³" -> Предел поглощения: 1600 кг/м³ | F9: =IF(C9>'Входные данные'!$C$58, "КРИТИЧЕСКИЙ РИСК: поглощение", "В норме") -> В норме
B10: Минимальный коэффициент запаса по ECD | C10: =MIN(Расчёт!AO5:AO14) -> 1.0496095 | D10: — | E10: Норматив: 1.05 | F10: =IF(C10<1, "АВАРИЙНО: поглощение", IF(C10<1.05, "Внимание: риск поглощения", "В норме")) -> Внимание: риск поглощения
B11: Минимальный запас прочности по смятию (Collapse) | C11: =MIN(Расчёт!AR5:AR14) -> 0.91247532 | D11: — | E11: Норматив: 1.15 | F11: =IF(C11<1, "АВАРИЙНО: смятие колонны", IF(C11<1.15, "Внимание: низкий запас", "В норме")) -> АВАРИЙНО: смятие колонны
B12: Минимальный запас прочности по разрыву (Burst) | C12: =MIN(Расчёт!AS5:AS14) -> 2.1701431 | D12: — | E12: Норматив: 1.10 | F12: =IF(C12<1, "АВАРИЙНО: разрыв колонны", IF(C12<1.1, "Внимание: низкий запас", "В норме")) -> В норме
B13: Минимальный запас по фон Мизесу (VM Stress) | C13: =MIN(Расчёт!AQ5:AQ14) -> 2.3376156 | D13: — | E13: Норматив: 1.25 | F13: =IF(C13<1, "АВАРИЙНО: текучесть стали", IF(C13<1.25, "Внимание: низкий запас", "В норме")) -> В норме
B14: Максимальное давление поршневания (Surge) | C14: =MAX(Расчёт!AL5:AL14) -> 4.6101554 | D14: МПа | E14: Справочно | F14: =""
B15: Максимальная температура в стволе | C15: =MAX(Расчёт!X5:X14) -> 116.75 | D15: °C | E15: Предел раствора: 120 °C | F15: =IF(C15>120, "Внимание: деструкция раствора", "В норме") -> В норме
B16: Количество осложненных интервалов скважины | C16: =COUNTIF(Расчёт!Y5:Y14, "<>Норма") -> 10 | D16: шт. | E16: Целевое значение: 0 | F16: =IF(C16>0, "Внимание: требуются мероприятия", "В норме") -> Внимание: требуются мероприятия
B18: 2. Выявленные осложненные интервалы (требуют внимания)
B19: № | C19: Интервал глубин MD, м | D19: Тип ствола | E19: Характер угрозы / Статус | F19: Инженерный показатель
B20: =IF(Расчёт!Y5<>"Норма",Расчёт!B5,"") -> 1 | C20: =IF(Расчёт!Y5<>"Норма",Расчёт!C5&" - "&Расчёт!D5,"") -> 0 - 300 | D20: =IF(Расчёт!Y5<>"Норма",IF(Расчёт!I5="обс.","Обсаженный","Открытый"),"") -> Обсаженный | E20: =IF(Расчёт!Y5<>"Норма",Расчёт!Y5,"") -> ОПАСНО: спирал. изгиб | F20: =IF(Расчёт!Y5<>"Норма",IF(Расчёт!W5>0.5,TEXT(Расчёт!W5,"0.00")&" (изгиб)",IF(Расчёт!AO5<1.05,TEXT(Расчёт!AN5,"0")&" кг/м³ (ECD)",IF(Расчёт!AR5<1.15,TEXT(Расчёт!AR5,"0.00")&" (SF_смятие)",IF(Расчёт!AS5<1.1,TEXT(Расчёт!AS5,"0.00")&" (SF_разрыв)",IF(Расчёт!AQ5<1.25,TEXT(Расчёт!AQ5,"0.00")&" (SF_прочн)",TEXT(Расчёт!S5,"0")&" т (нагр)"))))),"") -> #VALUE!
B21: =IF(Расчёт!Y6<>"Норма",Расчёт!B6,"") -> 2 | C21: =IF(Расчёт!Y6<>"Норма",Расчёт!C6&" - "&Расчёт!D6,"") -> 300 - 600 | D21: =IF(Расчёт!Y6<>"Норма",IF(Расчёт!I6="обс.","Обсаженный","Открытый"),"") -> Обсаженный | E21: =IF(Расчёт!Y6<>"Норма",Расчёт!Y6,"") -> ОПАСНО: спирал. изгиб | F21: =IF(Расчёт!Y6<>"Норма",IF(Расчёт!W6>0.5,TEXT(Расчёт!W6,"0.00")&" (изгиб)",IF(Расчёт!AO6<1.05,TEXT(Расчёт!AN6,"0")&" кг/м³ (ECD)",IF(Расчёт!AR6<1.15,TEXT(Расчёт!AR6,"0.00")&" (SF_смятие)",IF(Расчёт!AS6<1.1,TEXT(Расчёт!AS6,"0.00")&" (SF_разрыв)",IF(Расчёт!AQ6<1.25,TEXT(Расчёт!AQ6,"0.00")&" (SF_прочн)",TEXT(Расчёт!S6,"0")&" т (нагр)"))))),"") -> #VALUE!
B22: =IF(Расчёт!Y7<>"Норма",Расчёт!B7,"") -> 3 | C22: =IF(Расчёт!Y7<>"Норма",Расчёт!C7&" - "&Расчёт!D7,"") -> 600 - 750 | D22: =IF(Расчёт!Y7<>"Норма",IF(Расчёт!I7="обс.","Обсаженный","Открытый"),"") -> Обсаженный | E22: =IF(Расчёт!Y7<>"Норма",Расчёт!Y7,"") -> ОПАСНО: спирал. изгиб | F22: =IF(Расчёт!Y7<>"Норма",IF(Расчёт!W7>0.5,TEXT(Расчёт!W7,"0.00")&" (изгиб)",IF(Расчёт!AO7<1.05,TEXT(Расчёт!AN7,"0")&" кг/м³ (ECD)",IF(Расчёт!AR7<1.15,TEXT(Расчёт!AR7,"0.00")&" (SF_смятие)",IF(Расчёт!AS7<1.1,TEXT(Расчёт!AS7,"0.00")&" (SF_разрыв)",IF(Расчёт!AQ7<1.25,TEXT(Расчёт!AQ7,"0.00")&" (SF_прочн)",TEXT(Расчёт!S7,"0")&" т (нагр)"))))),"") -> #VALUE!
B23: =IF(Расчёт!Y8<>"Норма",Расчёт!B8,"") -> 4 | C23: =IF(Расчёт!Y8<>"Норма",Расчёт!C8&" - "&Расчёт!D8,"") -> 750 - 900 | D23: =IF(Расчёт!Y8<>"Норма",IF(Расчёт!I8="обс.","Обсаженный","Открытый"),"") -> Обсаженный | E23: =IF(Расчёт!Y8<>"Норма",Расчёт!Y8,"") -> ОПАСНО: спирал. изгиб | F23: =IF(Расчёт!Y8<>"Норма",IF(Расчёт!W8>0.5,TEXT(Расчёт!W8,"0.00")&" (изгиб)",IF(Расчёт!AO8<1.05,TEXT(Расчёт!AN8,"0")&" кг/м³ (ECD)",IF(Расчёт!AR8<1.15,TEXT(Расчёт!AR8,"0.00")&" (SF_смятие)",IF(Расчёт!AS8<1.1,TEXT(Расчёт!AS8,"0.00")&" (SF_разрыв)",IF(Расчёт!AQ8<1.25,TEXT(Расчёт!AQ8,"0.00")&" (SF_прочн)",TEXT(Расчёт!S8,"0")&" т (нагр)"))))),"") -> #VALUE!
B24: =IF(Расчёт!Y9<>"Норма",Расчёт!B9,"") -> 5 | C24: =IF(Расчёт!Y9<>"Норма",Расчёт!C9&" - "&Расчёт!D9,"") -> 900 - 1050 | D24: =IF(Расчёт!Y9<>"Норма",IF(Расчёт!I9="обс.","Обсаженный","Открытый"),"") -> Обсаженный | E24: =IF(Расчёт!Y9<>"Норма",Расчёт!Y9,"") -> Внимание: синус. изгиб | F24: =IF(Расчёт!Y9<>"Норма",IF(Расчёт!W9>0.5,TEXT(Расчёт!W9,"0.00")&" (изгиб)",IF(Расчёт!AO9<1.05,TEXT(Расчёт!AN9,"0")&" кг/м³ (ECD)",IF(Расчёт!AR9<1.15,TEXT(Расчёт!AR9,"0.00")&" (SF_смятие)",IF(Расчёт!AS9<1.1,TEXT(Расчёт!AS9,"0.00")&" (SF_разрыв)",IF(Расчёт!AQ9<1.25,TEXT(Расчёт!AQ9,"0.00")&" (SF_прочн)",TEXT(Расчёт!S9,"0")&" т (нагр)"))))),"") -> #VALUE!
B25: =IF(Расчёт!Y10<>"Норма",Расчёт!B10,"") -> 6 | C25: =IF(Расчёт!Y10<>"Норма",Расчёт!C10&" - "&Расчёт!D10,"") -> 1050 - 1500 | D25: =IF(Расчёт!Y10<>"Норма",IF(Расчёт!I10="обс.","Обсаженный","Открытый"),"") -> Обсаженный | E25: =IF(Расчёт!Y10<>"Норма",Расчёт!Y10,"") -> Внимание: синус. изгиб | F25: =IF(Расчёт!Y10<>"Норма",IF(Расчёт!W10>0.5,TEXT(Расчёт!W10,"0.00")&" (изгиб)",IF(Расчёт!AO10<1.05,TEXT(Расчёт!AN10,"0")&" кг/м³ (ECD)",IF(Расчёт!AR10<1.15,TEXT(Расчёт!AR10,"0.00")&" (SF_смятие)",IF(Расчёт!AS10<1.1,TEXT(Расчёт!AS10,"0.00")&" (SF_разрыв)",IF(Расчёт!AQ10<1.25,TEXT(Расчёт!AQ10,"0.00")&" (SF_прочн)",TEXT(Расчёт!S10,"0")&" т (нагр)"))))),"") -> #VALUE!
B26: =IF(Расчёт!Y11<>"Норма",Расчёт!B11,"") -> 7 | C26: =IF(Расчёт!Y11<>"Норма",Расчёт!C11&" - "&Расчёт!D11,"") -> 1500 - 2000 | D26: =IF(Расчёт!Y11<>"Норма",IF(Расчёт!I11="обс.","Обсаженный","Открытый"),"") -> Обсаженный | E26: =IF(Расчёт!Y11<>"Норма",Расчёт!Y11,"") -> Внимание: синус. изгиб | F26: =IF(Расчёт!Y11<>"Норма",IF(Расчёт!W11>0.5,TEXT(Расчёт!W11,"0.00")&" (изгиб)",IF(Расчёт!AO11<1.05,TEXT(Расчёт!AN11,"0")&" кг/м³ (ECD)",IF(Расчёт!AR11<1.15,TEXT(Расчёт!AR11,"0.00")&" (SF_смятие)",IF(Расчёт!AS11<1.1,TEXT(Расчёт!AS11,"0.00")&" (SF_разрыв)",IF(Расчёт!AQ11<1.25,TEXT(Расчёт!AQ11,"0.00")&" (SF_прочн)",TEXT(Расчёт!S11,"0")&" т (нагр)"))))),"") -> #VALUE!
B27: =IF(Расчёт!Y12<>"Норма",Расчёт!B12,"") -> 8 | C27: =IF(Расчёт!Y12<>"Норма",Расчёт!C12&" - "&Расчёт!D12,"") -> 2000 - 2500 | D27: =IF(Расчёт!Y12<>"Норма",IF(Расчёт!I12="обс.","Обсаженный","Открытый"),"") -> Открытый | E27: =IF(Расчёт!Y12<>"Норма",Расчёт!Y12,"") -> Внимание: синус. изгиб | F27: =IF(Расчёт!Y12<>"Норма",IF(Расчёт!W12>0.5,TEXT(Расчёт!W12,"0.00")&" (изгиб)",IF(Расчёт!AO12<1.05,TEXT(Расчёт!AN12,"0")&" кг/м³ (ECD)",IF(Расчёт!AR12<1.15,TEXT(Расчёт!AR12,"0.00")&" (SF_смятие)",IF(Расчёт!AS12<1.1,TEXT(Расчёт!AS12,"0.00")&" (SF_разрыв)",IF(Расчёт!AQ12<1.25,TEXT(Расчёт!AQ12,"0.00")&" (SF_прочн)",TEXT(Расчёт!S12,"0")&" т (нагр)"))))),"") -> #VALUE!
B28: =IF(Расчёт!Y13<>"Норма",Расчёт!B13,"") -> 9 | C28: =IF(Расчёт!Y13<>"Норма",Расчёт!C13&" - "&Расчёт!D13,"") -> 2500 - 3000 | D28: =IF(Расчёт!Y13<>"Норма",IF(Расчёт!I13="обс.","Обсаженный","Открытый"),"") -> Открытый | E28: =IF(Расчёт!Y13<>"Норма",Расчёт!Y13,"") -> ОПАСНО: спирал. изгиб | F28: =IF(Расчёт!Y13<>"Норма",IF(Расчёт!W13>0.5,TEXT(Расчёт!W13,"0.00")&" (изгиб)",IF(Расчёт!AO13<1.05,TEXT(Расчёт!AN13,"0")&" кг/м³ (ECD)",IF(Расчёт!AR13<1.15,TEXT(Расчёт!AR13,"0.00")&" (SF_смятие)",IF(Расчёт!AS13<1.1,TEXT(Расчёт!AS13,"0.00")&" (SF_разрыв)",IF(Расчёт!AQ13<1.25,TEXT(Расчёт!AQ13,"0.00")&" (SF_прочн)",TEXT(Расчёт!S13,"0")&" т (нагр)"))))),"") -> #VALUE!
B29: =IF(Расчёт!Y14<>"Норма",Расчёт!B14,"") -> 10 | C29: =IF(Расчёт!Y14<>"Норма",Расчёт!C14&" - "&Расчёт!D14,"") -> 3000 - 3450 | D29: =IF(Расчёт!Y14<>"Норма",IF(Расчёт!I14="обс.","Обсаженный","Открытый"),"") -> Открытый | E29: =IF(Расчёт!Y14<>"Норма",Расчёт!Y14,"") -> ОПАСНО: спирал. изгиб | F29: =IF(Расчёт!Y14<>"Норма",IF(Расчёт!W14>0.5,TEXT(Расчёт!W14,"0.00")&" (изгиб)",IF(Расчёт!AO14<1.05,TEXT(Расчёт!AN14,"0")&" кг/м³ (ECD)",IF(Расчёт!AR14<1.15,TEXT(Расчёт!AR14,"0.00")&" (SF_смятие)",IF(Расчёт!AS14<1.1,TEXT(Расчёт!AS14,"0.00")&" (SF_разрыв)",IF(Расчёт!AQ14<1.25,TEXT(Расчёт!AQ14,"0.00")&" (SF_прочн)",TEXT(Расчёт!S14,"0")&" т (нагр)"))))),"") -> #VALUE!
B31: 3. Инженерно-технологические рекомендации по спуску
B32: • Буровой раствор: Контролировать плотность и реологию. При повышении ECD выше 1550 кг/м³ снизить скорость спуска.
B33: • Скорость спуска: Поддерживать в безопасных пределах (≤ 0.5 м/с) для исключения гидроразрыва и поглощений раствора.
B34: • Риск изгиба (Buckling): В интервалах набора кривизны (600-1050 м) и на забое (3000-3450 м) установить централизаторы для снижения трения и предотвращения спирального заклинивания.
B35: • Прочность колонны (Collapse/Burst): Смятие критично на забое (SF_смятие = 1.05 при разгрузке 180 т). При разгрузке инструмента не превышать допустимые осевые усилия.
B36: • Напряжения по фон Мизесу: При давлении опрессовки 30 МПа коэффициент прочности равен 2.34 (безопасно). Не допускать превышения опрессовки свыше 40 МПа.
B37: • Мониторинг веса на крюке: При превышении затяжек свыше 200 т (лимит) — остановить спуск, расхаживать и промывать скважину.
